Workbook

Sheet List
A1: 1 | B1: When buying a boat, I do a lot of shopping around and visit multiple dealers
A2: 2 | B2: When buying a bot, getting the lowest P is more important than brand
A3: 3 | B3: The brand of the boat I buy says a lot about who I am
A4: 4 | B4: I only consider buying a boat from a reputable brand
A5: 5 | B5: I am willing to pay a premium for a brand with a reputation for high quality
A6: 6 | B6: Owning a boat is a way of rewarding myself for hard work
A7: 7 | B7: Owning a boat gives me a sense of achievement
A8: 8 | B8: When buying a boat, functionality is more important than style
A9: 9 | B9: I see my boat as status symbol
A10: 10 | B10: When buying a boat, I rely more on expert opinion than my own
A11: 11 | B11: I tend to perform minor boat repairs and maintenance on my own
A12: 12 | B12: When it comes to boating, I tend to prefer a basic boat with little to no frills
... A29: 29 | B29: Boating is one of many things I do in my spare time

Sheet Eigenvalue varimax
B1: Component 1 - Early birds/crazy about boats/ experts
A2: 9 | B2: =+VLOOKUP(A2,List!$A$1:$B$29,2,FALSE) -> I see my boat as status symbol
A3: 26 | B3: =+VLOOKUP(A3,List!$A$1:$B$29,2,FALSE) -> Having a powerful boat is what is most important to me
A4: 3 | B4: =+VLOOKUP(A4,List!$A$1:$B$29,2,FALSE) -> The brand of the boat I buy says a lot about who I am
A5: 13 | B5: =+VLOOKUP(A5,List!$A$1:$B$29,2,FALSE) -> When buying a boat, I tend to buy the latest and greatest
A6: 27 | B6: =+VLOOKUP(A6,List!$A$1:$B$29,2,FALSE) -> Boating is the number one thing I do with my spare time
A7: 28 | B7: =+VLOOKUP(A7,List!$A$1:$B$29,2,FALSE) -> Boating is my true passion in life
A8: 14 | B8: =+VLOOKUP(A8,List!$A$1:$B$29,2,FALSE) -> When buying accessories for my boat, I tend to buy the latest and greatest
A9: 16 | B9: =+VLOOKUP(A9,List!$A$1:$B$29,2,FALSE) -> People tend to come to me for advice about boating
A10: 7 | B10: =+VLOOKUP(A10,List!$A$1:$B$29,2,FALSE) -> Owning a boat gives me a sense of achievement
A11: 17 | B11: =+VLOOKUP(A11,List!$A$1:$B$29,2,FALSE) -> I consider myself more knowledgeable about boating than the rest of my boating peers
A12: 20 | B12: =+VLOOKUP(A12,List!$A$1:$B$29,2,FALSE) -> When not on my boat, I often find myself doing boating related activities
B15: Component 2 - Getting away with boat
A16: 7 | B16: =+VLOOKUP(A16,List!$A$1:$B$29,2,FALSE) -> Owning a boat gives me a sense of achievement
A17: 6 | B17: =+VLOOKUP(A17,List!$A$1:$B$29,2,FALSE) -> Owning a boat is a way of rewarding myself for hard work
A18: 22 | B18: =+VLOOKUP(A18,List!$A$1:$B$29,2,FALSE) -> Boating helps me stay active
A19: 18 | B19: =+VLOOKUP(A19,List!$A$1:$B$29,2,FALSE) -> Boating gives me a feeling of adventure
A20: 24 | B20: =+VLOOKUP(A20,List!$A$1:$B$29,2,FALSE) -> Boating gives me an outlet to socialize with family/friends
A21: 21 | B21: =+VLOOKUP(A21,List!$A$1:$B$29,2,FALSE) -> Boating helps me escape from everyday life and relax
A22: 19 | B22: =+VLOOKUP(A22,List!$A$1:$B$29,2,FALSE) -> Boating allows me to experience nature
B25: Component 3 - brand lovers
A26: 5 | B26: =+VLOOKUP(A26,List!$A$1:$B$29,2,FALSE) -> I am willing to pay a premium for a brand with a reputation for high quality
A27: 15 | B27: =+VLOOKUP(A27,List!$A$1:$B$29,2,FALSE) -> I am serious about the technology on my boat
A28: 4 | B28: =+VLOOKUP(A28,List!$A$1:$B$29,2,FALSE) -> I only consider buying a boat from a reputable brand
B31: Component 4 - Experts
A32: 16 | B32: =+VLOOKUP(A32,List!$A$1:$B$29,2,FALSE) -> People tend to come to me for advice about boating
A33: 17 | B33: =+VLOOKUP(A33,List!$A$1:$B$29,2,FALSE) -> I consider myself more knowledgeable about boating than the rest of my boating peers
A34: 11 | B34: =+VLOOKUP(A34,List!$A$1:$B$29,2,FALSE) -> I tend to perform minor boat repairs and maintenance on my own
B37: Component 5 - Price conscious
A38: 2 | B38: =+VLOOKUP(A38,List!$A$1:$B$29,2,FALSE) -> When buying a bot, getting the lowest P is more important than brand
A39: 12 | B39: =+VLOOKUP(A39,List!$A$1:$B$29,2,FALSE) -> When it comes to boating, I tend to prefer a basic boat with little to no frills
A40: 8 | B40: =+VLOOKUP(A40,List!$A$1:$B$29,2,FALSE) -> When buying a boat, functionality is more important than style

Sheet Eigenvalue quatimax
B1: Component 1 -
A2: 28 | B2: =+VLOOKUP(A2,List!$A$1:$B$29,2,FALSE) -> Boating is my true passion in life
A3: 14 | B3: =+VLOOKUP(A3,List!$A$1:$B$29,2,FALSE) -> When buying accessories for my boat, I tend to buy the latest and greatest
A4: 20 | B4: =+VLOOKUP(A4,List!$A$1:$B$29,2,FALSE) -> When not on my boat, I often find myself doing boating related activities
A5: 27 | B5: =+VLOOKUP(A5,List!$A$1:$B$29,2,FALSE) -> Boating is the number one thing I do with my spare time
A6: 3 | B6: =+VLOOKUP(A6,List!$A$1:$B$29,2,FALSE) -> The brand of the boat I buy says a lot about who I am
A7: 7 | B7: =+VLOOKUP(A7,List!$A$1:$B$29,2,FALSE) -> Owning a boat gives me a sense of achievement
A8: 15 | B8: =+VLOOKUP(A8,List!$A$1:$B$29,2,FALSE) -> I am serious about the technology on my boat
A9: 16 | B9: =+VLOOKUP(A9,List!$A$1:$B$29,2,FALSE) -> People tend to come to me for advice about boating
A10: 13 | B10: =+VLOOKUP(A10,List!$A$1:$B$29,2,FALSE) -> When buying a boat, I tend to buy the latest and greatest
A11: 25 | B11: =+VLOOKUP(A11,List!$A$1:$B$29,2,FALSE) -> Being in charge of my boat is what is most important to me
A12: 6 | B12: =+VLOOKUP(A12,List!$A$1:$B$29,2,FALSE) -> Owning a boat is a way of rewarding myself for hard work
A13: 26 | B13: =+VLOOKUP(A13,List!$A$1:$B$29,2,FALSE) -> Having a powerful boat is what is most important to me
... A19: 18 | B19: =+VLOOKUP(A19,List!$A$1:$B$29,2,FALSE) -> Boating gives me a feeling of adventure
B22: Component 2 - Getting away with boat
A23: 21 | B23: =+VLOOKUP(A23,List!$A$1:$B$29,2,FALSE) -> Boating helps me escape from everyday life and relax
A24: 19 | B24: =+VLOOKUP(A24,List!$A$1:$B$29,2,FALSE) -> Boating allows me to experience nature
B27: Component 3 - price conscious
A28: 8 | B28: =+VLOOKUP(A28,List!$A$1:$B$29,2,FALSE) -> When buying a boat, functionality is more important than style
A29: 2 | B29: =+VLOOKUP(A29,List!$A$1:$B$29,2,FALSE) -> When buying a bot, getting the lowest P is more important than brand
A30: 12 | B30: =+VLOOKUP(A30,List!$A$1:$B$29,2,FALSE) -> When it comes to boating, I tend to prefer a basic boat with little to no frills
B33: Component 4 -
A34: 11 | B34: =+VLOOKUP(A34,List!$A$1:$B$29,2,FALSE) -> I tend to perform minor boat repairs and maintenance on my own
A35: 10 | B35: =+VLOOKUP(A35,List!$A$1:$B$29,2,FALSE) -> When buying a boat, I rely more on expert opinion than my own

Sheet Eigenvalue proxmax
B1: Component 1 -
A2: 9 | B2: =+VLOOKUP(A2,List!$A$1:$B$29,2,FALSE) -> I see my boat as status symbol
A3: 26 | B3: =+VLOOKUP(A3,List!$A$1:$B$29,2,FALSE) -> Having a powerful boat is what is most important to me
A4: 3 | B4: =+VLOOKUP(A4,List!$A$1:$B$29,2,FALSE) -> The brand of the boat I buy says a lot about who I am
A5: 13 | B5: =+VLOOKUP(A5,List!$A$1:$B$29,2,FALSE) -> When buying a boat, I tend to buy the latest and greatest
A6: 27 | B6: =+VLOOKUP(A6,List!$A$1:$B$29,2,FALSE) -> Boating is the number one thing I do with my spare time
A7: 14 | B7: =+VLOOKUP(A7,List!$A$1:$B$29,2,FALSE) -> When buying accessories for my boat, I tend to buy the latest and greatest
A8: 28 | B8: =+VLOOKUP(A8,List!$A$1:$B$29,2,FALSE) -> Boating is my true passion in life
A9: 7 | B9: =+VLOOKUP(A9,List!$A$1:$B$29,2,FALSE) -> Owning a boat gives me a sense of achievement
B12: Component 2 - Getting away with boat
A13: 7 | B13: =+VLOOKUP(A13,List!$A$1:$B$29,2,FALSE) -> Owning a boat gives me a sense of achievement
A14: 6 | B14: =+VLOOKUP(A14,List!$A$1:$B$29,2,FALSE) -> Owning a boat is a way of rewarding myself for hard work
A15: 22 | B15: =+VLOOKUP(A15,List!$A$1:$B$29,2,FALSE) -> Boating helps me stay active
A16: 24 | B16: =+VLOOKUP(A16,List!$A$1:$B$29,2,FALSE) -> Boating gives me an outlet to socialize with family/friends
A17: 18 | B17: =+VLOOKUP(A17,List!$A$1:$B$29,2,FALSE) -> Boating gives me a feeling of adventure
A18: 21 | B18: =+VLOOKUP(A18,List!$A$1:$B$29,2,FALSE) -> Boating helps me escape from everyday life and relax
A19: 19 | B19: =+VLOOKUP(A19,List!$A$1:$B$29,2,FALSE) -> Boating allows me to experience nature
B22: Component 3 -
A23: 16 | B23: =+VLOOKUP(A23,List!$A$1:$B$29,2,FALSE) -> People tend to come to me for advice about boating
A24: 17 | B24: =+VLOOKUP(A24,List!$A$1:$B$29,2,FALSE) -> I consider myself more knowledgeable about boating than the rest of my boating peers
A25: 10 | B25: =+VLOOKUP(A25,List!$A$1:$B$29,2,FALSE) -> When buying a boat, I rely more on expert opinion than my own
A26: 11 | B26: =+VLOOKUP(A26,List!$A$1:$B$29,2,FALSE) -> I tend to perform minor boat repairs and maintenance on my own
B30: Component 4 - Brand/Quality
A31: 5 | B31: =+VLOOKUP(A31,List!$A$1:$B$29,2,FALSE) -> I am willing to pay a premium for a brand with a reputation for high quality
A32: 4 | B32: =+VLOOKUP(A32,List!$A$1:$B$29,2,FALSE) -> I only consider buying a boat from a reputable brand
B35: Component 5 - Price conscious
A36: 2 | B36: =+VLOOKUP(A36,List!$A$1:$B$29,2,FALSE) -> When buying a bot, getting the lowest P is more important than brand
A37: 10 | B37: =+VLOOKUP(A37,List!$A$1:$B$29,2,FALSE) -> When buying a boat, I rely more on expert opinion than my own
A38: 12 | B38: =+VLOOKUP(A38,List!$A$1:$B$29,2,FALSE) -> When it comes to boating, I tend to prefer a basic boat with little to no frills
A39: 8 | B39: =+VLOOKUP(A39,List!$A$1:$B$29,2,FALSE) -> When buying a boat, functionality is more important than style

Sheet Eigenvalue oblimin
B1: Component 1 - Getting away with boat
A2: 21 | B2: =+VLOOKUP(A2,List!$A$1:$B$29,2,FALSE) -> Boating helps me escape from everyday life and relax
A3: 18 | B3: =+VLOOKUP(A3,List!$A$1:$B$29,2,FALSE) -> Boating gives me a feeling of adventure
A4: 19 | B4: =+VLOOKUP(A4,List!$A$1:$B$29,2,FALSE) -> Boating allows me to experience nature
A5: 6 | B5: =+VLOOKUP(A5,List!$A$1:$B$29,2,FALSE) -> Owning a boat is a way of rewarding myself for hard work
A6: 24 | B6: =+VLOOKUP(A6,List!$A$1:$B$29,2,FALSE) -> Boating gives me an outlet to socialize with family/friends
A7: 22 | B7: =+VLOOKUP(A7,List!$A$1:$B$29,2,FALSE) -> Boating helps me stay active
A8: 7 | B8: =+VLOOKUP(A8,List!$A$1:$B$29,2,FALSE) -> Owning a boat gives me a sense of achievement
B11: Component 2 - Expert
A12: 11 | B12: =+VLOOKUP(A12,List!$A$1:$B$29,2,FALSE) -> I tend to perform minor boat repairs and maintenance on my own
A13: 16 | B13: =+VLOOKUP(A13,List!$A$1:$B$29,2,FALSE) -> People tend to come to me for advice about boating
A14: 17 | B14: =+VLOOKUP(A14,List!$A$1:$B$29,2,FALSE) -> I consider myself more knowledgeable about boating than the rest of my boating peers
B17: Component 3 - High quality + brand
A18: 15 | B18: =+VLOOKUP(A18,List!$A$1:$B$29,2,FALSE) -> I am serious about the technology on my boat
A19: 4 | B19: =+VLOOKUP(A19,List!$A$1:$B$29,2,FALSE) -> I only consider buying a boat from a reputable brand
A20: 5 | B20: =+VLOOKUP(A20,List!$A$1:$B$29,2,FALSE) -> I am willing to pay a premium for a brand with a reputation for high quality
A21: 14 | B21: =+VLOOKUP(A21,List!$A$1:$B$29,2,FALSE) -> When buying accessories for my boat, I tend to buy the latest and greatest
A22: 13 | B22: =+VLOOKUP(A22,List!$A$1:$B$29,2,FALSE) -> When buying a boat, I tend to buy the latest and greatest
B25: Component 4 - Status
A26: 3 | B26: =+VLOOKUP(A26,List!$A$1:$B$29,2,FALSE) -> The brand of the boat I buy says a lot about who I am
A27: 9 | B27: =+VLOOKUP(A27,List!$A$1:$B$29,2,FALSE) -> I see my boat as status symbol
A28: 26 | B28: =+VLOOKUP(A28,List!$A$1:$B$29,2,FALSE) -> Having a powerful boat is what is most important to me
B31: Component 5 - Price conscious
A32: 10 | B32: =+VLOOKUP(A32,List!$A$1:$B$29,2,FALSE) -> When buying a boat, I rely more on expert opinion than my own
A33: 8 | B33: =+VLOOKUP(A33,List!$A$1:$B$29,2,FALSE) -> When buying a boat, functionality is more important than style
A34: 2 | B34: =+VLOOKUP(A34,List!$A$1:$B$29,2,FALSE) -> When buying a bot, getting the lowest P is more important than brand
A35: 12 | B35: =+VLOOKUP(A35,List!$A$1:$B$29,2,FALSE) -> When it comes to boating, I tend to prefer a basic boat with little to no frills

Sheet Eigenvalue simplimax
B1: Component 1 -
A2: 28 | B2: =+VLOOKUP(A2,List!$A$1:$B$29,2,FALSE) -> Boating is my true passion in life
A3: 27 | B3: =+VLOOKUP(A3,List!$A$1:$B$29,2,FALSE) -> Boating is the number one thing I do with my spare time
A4: 20 | B4: =+VLOOKUP(A4,List!$A$1:$B$29,2,FALSE) -> When not on my boat, I often find myself doing boating related activities
A5: 3 | B5: =+VLOOKUP(A5,List!$A$1:$B$29,2,FALSE) -> The brand of the boat I buy says a lot about who I am
A6: 16 | B6: =+VLOOKUP(A6,List!$A$1:$B$29,2,FALSE) -> People tend to come to me for advice about boating
A7: 7 | B7: =+VLOOKUP(A7,List!$A$1:$B$29,2,FALSE) -> Owning a boat gives me a sense of achievement
A8: 9 | B8: =+VLOOKUP(A8,List!$A$1:$B$29,2,FALSE) -> I see my boat as status symbol
A9: 14 | B9: =+VLOOKUP(A9,List!$A$1:$B$29,2,FALSE) -> When buying accessories for my boat, I tend to buy the latest and greatest
A10: 26 | B10: =+VLOOKUP(A10,List!$A$1:$B$29,2,FALSE) -> Having a powerful boat is what is most important to me
A11: 13 | B11: =+VLOOKUP(A11,List!$A$1:$B$29,2,FALSE) -> When buying a boat, I tend to buy the latest and greatest
A12: 17 | B12: =+VLOOKUP(A12,List!$A$1:$B$29,2,FALSE) -> I consider myself more knowledgeable about boating than the rest of my boating peers
A13: 15 | B13: =+VLOOKUP(A13,List!$A$1:$B$29,2,FALSE) -> I am serious about the technology on my boat
... A19: 18 | B19: =+VLOOKUP(A19,List!$A$1:$B$29,2,FALSE) -> Boating gives me a feeling of adventure
B22: Component 2 - Getting away with boat
A23: 18 | B23: =+VLOOKUP(A23,List!$A$1:$B$29,2,FALSE) -> Boating gives me a feeling of adventure
A24: 21 | B24: =+VLOOKUP(A24,List!$A$1:$B$29,2,FALSE) -> Boating helps me escape from everyday life and relax
A25: 19 | B25: =+VLOOKUP(A25,List!$A$1:$B$29,2,FALSE) -> Boating allows me to experience nature
B28: Component 3 - price conscious
A29: 2 | B29: =+VLOOKUP(A29,List!$A$1:$B$29,2,FALSE) -> When buying a bot, getting the lowest P is more important than brand
A30: 12 | B30: =+VLOOKUP(A30,List!$A$1:$B$29,2,FALSE) -> When it comes to boating, I tend to prefer a basic boat with little to no frills
B33: Component 4 -
A34: 10 | B34: =+VLOOKUP(A34,List!$A$1:$B$29,2,FALSE) -> When buying a boat, I rely more on expert opinion than my own
B36: Component 5 -
A37: 4 | B37: =+VLOOKUP(A37,List!$A$1:$B$29,2,FALSE) -> I only consider buying a boat from a reputable brand

Sheet Eigenvalue cluster
B1: Component 1 -
A2: 9 | B2: =+VLOOKUP(A2,List!$A$1:$B$29,2,FALSE) -> I see my boat as status symbol
A3: 26 | B3: =+VLOOKUP(A3,List!$A$1:$B$29,2,FALSE) -> Having a powerful boat is what is most important to me
A4: 16 | B4: =+VLOOKUP(A4,List!$A$1:$B$29,2,FALSE) -> People tend to come to me for advice about boating
A5: 27 | B5: =+VLOOKUP(A5,List!$A$1:$B$29,2,FALSE) -> Boating is the number one thing I do with my spare time
A6: 3 | B6: =+VLOOKUP(A6,List!$A$1:$B$29,2,FALSE) -> The brand of the boat I buy says a lot about who I am
A7: 17 | B7: =+VLOOKUP(A7,List!$A$1:$B$29,2,FALSE) -> I consider myself more knowledgeable about boating than the rest of my boating peers
A8: 28 | B8: =+VLOOKUP(A8,List!$A$1:$B$29,2,FALSE) -> Boating is my true passion in life
A9: 13 | B9: =+VLOOKUP(A9,List!$A$1:$B$29,2,FALSE) -> When buying a boat, I tend to buy the latest and greatest
A10: 20 | B10: =+VLOOKUP(A10,List!$A$1:$B$29,2,FALSE) -> When not on my boat, I often find myself doing boating related activities
A11: 14 | B11: =+VLOOKUP(A11,List!$A$1:$B$29,2,FALSE) -> When buying accessories for my boat, I tend to buy the latest and greatest
A12: 7 | B12: =+VLOOKUP(A12,List!$A$1:$B$29,2,FALSE) -> Owning a boat gives me a sense of achievement
B15: Component 2 - Getting away with boat
A16: 6 | B16: =+VLOOKUP(A16,List!$A$1:$B$29,2,FALSE) -> Owning a boat is a way of rewarding myself for hard work
A17: 22 | B17: =+VLOOKUP(A17,List!$A$1:$B$29,2,FALSE) -> Boating helps me stay active
A18: 18 | B18: =+VLOOKUP(A18,List!$A$1:$B$29,2,FALSE) -> Boating gives me a feeling of adventure
A19: 24 | B19: =+VLOOKUP(A19,List!$A$1:$B$29,2,FALSE) -> Boating gives me an outlet to socialize with family/friends
A20: 21 | B20: =+VLOOKUP(A20,List!$A$1:$B$29,2,FALSE) -> Boating helps me escape from everyday life and relax
A21: 19 | B21: =+VLOOKUP(A21,List!$A$1:$B$29,2,FALSE) -> Boating allows me to experience nature
B24: Component 3 - Brand
A25: 5 | B25: =+VLOOKUP(A25,List!$A$1:$B$29,2,FALSE) -> I am willing to pay a premium for a brand with a reputation for high quality
A26: 4 | B26: =+VLOOKUP(A26,List!$A$1:$B$29,2,FALSE) -> I only consider buying a boat from a reputable brand
B29: Component 4 - Price conscious
A30: 2 | B30: =+VLOOKUP(A30,List!$A$1:$B$29,2,FALSE) -> When buying a bot, getting the lowest P is more important than brand
A31: 12 | B31: =+VLOOKUP(A31,List!$A$1:$B$29,2,FALSE) -> When it comes to boating, I tend to prefer a basic boat with little to no frills
A32: 8 | B32: =+VLOOKUP(A32,List!$A$1:$B$29,2,FALSE) -> When buying a boat, functionality is more important than style
B35: Component 5 - Expertise
A36: 11 | B36: =+VLOOKUP(A36,List!$A$1:$B$29,2,FALSE) -> I tend to perform minor boat repairs and maintenance on my own
A37: 10 | B37: =+VLOOKUP(A37,List!$A$1:$B$29,2,FALSE) -> When buying a boat, I rely more on expert opinion than my own

Sheet Eigenvalue none
B1: Component 1 -
A2: 28 | B2: =+VLOOKUP(A2,List!$A$1:$B$29,2,FALSE) -> Boating is my true passion in life
A3: 14 | B3: =+VLOOKUP(A3,List!$A$1:$B$29,2,FALSE) -> When buying accessories for my boat, I tend to buy the latest and greatest
A4: 20 | B4: =+VLOOKUP(A4,List!$A$1:$B$29,2,FALSE) -> When not on my boat, I often find myself doing boating related activities
A5: 27 | B5: =+VLOOKUP(A5,List!$A$1:$B$29,2,FALSE) -> Boating is the number one thing I do with my spare time
A6: 3 | B6: =+VLOOKUP(A6,List!$A$1:$B$29,2,FALSE) -> The brand of the boat I buy says a lot about who I am
A7: 7 | B7: =+VLOOKUP(A7,List!$A$1:$B$29,2,FALSE) -> Owning a boat gives me a sense of achievement
A8: 15 | B8: =+VLOOKUP(A8,List!$A$1:$B$29,2,FALSE) -> I am serious about the technology on my boat
A9: 16 | B9: =+VLOOKUP(A9,List!$A$1:$B$29,2,FALSE) -> People tend to come to me for advice about boating
A10: 13 | B10: =+VLOOKUP(A10,List!$A$1:$B$29,2,FALSE) -> When buying a boat, I tend to buy the latest and greatest
A11: 25 | B11: =+VLOOKUP(A11,List!$A$1:$B$29,2,FALSE) -> Being in charge of my boat is what is most important to me
A12: 6 | B12: =+VLOOKUP(A12,List!$A$1:$B$29,2,FALSE) -> Owning a boat is a way of rewarding myself for hard work
A13: 26 | B13: =+VLOOKUP(A13,List!$A$1:$B$29,2,FALSE) -> Having a powerful boat is what is most important to me
... A19: 18 | B19: =+VLOOKUP(A19,List!$A$1:$B$29,2,FALSE) -> Boating gives me a feeling of adventure
B22: Component 2 - Getting away with boat
A23: 21 | B23: =+VLOOKUP(A23,List!$A$1:$B$29,2,FALSE) -> Boating helps me escape from everyday life and relax
A24: 19 | B24: =+VLOOKUP(A24,List!$A$1:$B$29,2,FALSE) -> Boating allows me to experience nature
B27: Component 3 - Price conscious
A28: 8 | B28: =+VLOOKUP(A28,List!$A$1:$B$29,2,FALSE) -> When buying a boat, functionality is more important than style
A29: 2 | B29: =+VLOOKUP(A29,List!$A$1:$B$29,2,FALSE) -> When buying a bot, getting the lowest P is more important than brand
A30: 13 | B30: =+VLOOKUP(A30,List!$A$1:$B$29,2,FALSE) -> When buying a boat, I tend to buy the latest and greatest
B33: Component 4 - Expertise
A34: 11 | B34: =+VLOOKUP(A34,List!$A$1:$B$29,2,FALSE) -> I tend to perform minor boat repairs and maintenance on my own
A35: 10 | B35: =+VLOOKUP(A35,List!$A$1:$B$29,2,FALSE) -> When buying a boat, I rely more on expert opinion than my own

Sheet Sheet2
A3: METHOD | B3: QUESTION | C3: Sum of RANKComp.1 | D3: Sum of RANKComp.2 | E3: Sum of RANKComp.3 | F3: Sum of RANKComp.4 | G3: Sum of RANKComp.5 | H3: Sum of RANKComp.6 | I3: Sum of RANKComp.7 | J3: Sum of RANKComp.8 | K3: Sum of RANKComp.9 | L3: Sum of RANKComp.10 | M3: Sum of RANKComp.11 | N3: Sum of RANKComp.12
A4: VARIANCE - VARIMAX - 70% | B4: 1 | C4: 0 | D4: 0 | E4: 0 | F4: 0 | G4: 0 | H4: 0 | I4: 0 | J4: 0 | K4: 0 | L4: 1 | M4: 0 | N4: 0
A5: VARIANCE - VARIMAX - 70% | B5: 2 | C5: 0 | D5: 0 | E5: 0 | F5: 0 | G5: 2 | H5: 0 | I5: 0 | J5: 0 | K5: 0 | L5: 0 | M5: 0 | N5: 0
A6: VARIANCE - VARIMAX - 70% | B6: 3 | C6: 0 | D6: 0 | E6: 0 | F6: 1 | G6: 0 | H6: 0 | I6: 0 | J6: 0 | K6: 0 | L6: 0 | M6: 0 | N6: 0
A7: VARIANCE - VARIMAX - 70% | B7: 4 | C7: 0 | D7: 0 | E7: 0 | F7: 0 | G7: 0 | H7: 0 | I7: 1 | J7: 0 | K7: 0 | L7: 0 | M7: 0 | N7: 0
A8: VARIANCE - VARIMAX - 70% | B8: 5 | C8: 0 | D8: 0 | E8: 0 | F8: 0 | G8: 0 | H8: 0 | I8: 0 | J8: 0 | K8: 0 | L8: 0 | M8: 0 | N8: 0
A9: VARIANCE - VARIMAX - 70% | B9: 6 | C9: 0 | D9: 0 | E9: 0 | F9: 3 | G9: 0 | H9: 0 | I9: 0 | J9: 0 | K9: 0 | L9: 0 | M9: 0 | N9: 0
A10: VARIANCE - VARIMAX - 70% | B10: 7 | C10: 0 | D10: 0 | E10: 0 | F10: 4 | G10: 0 | H10: 0 | I10: 0 | J10: 0 | K10: 0 | L10: 0 | M10: 0 | N10: 0
A11: VARIANCE - VARIMAX - 70% | B11: 8 | C11: 0 | D11: 0 | E11: 0 | F11: 0 | G11: 0 | H11: 0 | I11: 0 | J11: 0 | K11: 1 | L11: 0 | M11: 0 | N11: 0
A12: VARIANCE - VARIMAX - 70% | B12: 9 | C12: 0 | D12: 0 | E12: 0 | F12: 2 | G12: 0 | H12: 0 | I12: 0 | J12: 0 | K12: 0 | L12: 0 | M12: 0 | N12: 0
A13: VARIANCE - VARIMAX - 70% | B13: 10 | C13: 0 | D13: 0 | E13: 0 | F13: 0 | G13: 0 | H13: 0 | I13: 0 | J13: 1 | K13: 0 | L13: 0 | M13: 0 | N13: 0
A14: VARIANCE - VARIMAX - 70% | B14: 11 | C14: 0 | D14: 0 | E14: 0 | F14: 0 | G14: 0 | H14: 1 | I14: 0 | J14: 0 | K14: 0 | L14: 0 | M14: 0 | N14: 0
A15: VARIANCE - VARIMAX - 70% | B15: 12 | C15: 0 | D15: 0 | E15: 0 | F15: 0 | G15: 1 | H15: 0 | I15: 0 | J15: 0 | K15: 0 | L15: 0 | M15: 0 | N15: 0
... A32: VARIANCE - VARIMAX - 70% | B32: 29 | C32: 0 | D32: 0 | E32: 0 | F32: 0 | G32: 0 | H32: 0 | I32: 0 | J32: 0 | K32: 0 | L32: 0 | M32: 1 | N32: 0
A33: Grand Total | C33: 21 | D33: 6 | E33: 6 | F33: 10 | G33: 3 | H33: 1 | I33: 1 | J33: 1 | K33: 1 | L33: 1 | M33: 1 | N33: 1

Sheet Variance - 70%
A1: QUESTION | B1: Comp.1 | C1: Comp.2 | D1: Comp.3 | E1: Comp.4 | F1: Comp.5 | G1: Comp.6 | H1: Comp.7 | I1: Comp.8 | J1: Comp.9 | K1: Comp.10 | L1: Comp.11 | M1: Comp.12 | N1: RANKComp.1 | O1: RANKComp.2 | P1: RANKComp.3 | Q1: RANKComp.4 | R1: RANKComp.5 | S1: RANKComp.6 | T1: RANKComp.7 | U1: RANKComp.8 | V1: RANKComp.9 | W1: RANKComp.10 | X1: RANKComp.11 | Y1: RANKComp.12 | Z1: METHOD | AC1: Component 1 - Boat lover
A2: 27 | B2: 0.76 | N2: =IF(B2>0,1,0) -> 1 | O2: =IF(C2>0,1,0) -> 0 | P2: =IF(D2>0,1,0) -> 0 | Q2: =IF(E2>0,1,0) -> 0 | R2: =IF(F2>0,1,0) -> 0 | S2: =IF(G2>0,1,0) -> 0 | T2: =IF(H2>0,1,0) -> 0 | U2: =IF(I2>0,1,0) -> 0 | ... Y2: =IF(M2>0,1,0) -> 0 | Z2: VARIANCE - VARIMAX - 70% | AB2: 1 | AC2: =IFERROR(INDEX($A$2:$A$30,MATCH(AB2,$N$2:$N$30,0)),"") -> 27 | AD2: =IFERROR(VLOOKUP(AC2,List!$A$1:$B$29,2,FALSE),"") -> Boating is the number one thing I do with my spare time
A3: 28 | B3: 0.75 | N3: =IF(B3>0,1+COUNTIFS(N$2:N2,">="&1),0) -> 2 | O3: =IF(C3>0,1+COUNTIFS(O$2:O2,">="&1),0) -> 0 | P3: =IF(D3>0,1+COUNTIFS(P$2:P2,">="&1),0) -> 0 | Q3: =IF(E3>0,1+COUNTIFS(Q$2:Q2,">="&1),0) -> 0 | R3: =IF(F3>0,1+COUNTIFS(R$2:R2,">="&1),0) -> 0 | S3: =IF(G3>0,1+COUNTIFS(S$2:S2,">="&1),0) -> 0 | T3: =IF(H3>0,1+COUNTIFS(T$2:T2,">="&1),0) -> 0 | U3: =IF(I3>0,1+COUNTIFS(U$2:U2,">="&1),0) -> 0 | ... Y3: =IF(M3>0,1+COUNTIFS(Y$2:Y2,">="&1),0) -> 0 | Z3: VARIANCE - VARIMAX - 70% | AB3: 2 | AC3: =IFERROR(INDEX($A$2:$A$30,MATCH(AB3,$N$2:$N$30,0)),"") -> 28 | AD3: =IFERROR(VLOOKUP(AC3,List!$A$1:$B$29,2,FALSE),"") -> Boating is my true passion in life
A4: 20 | B4: 0.64 | N4: =IF(B4>0,1+COUNTIFS(N$2:N3,">="&1),0) -> 3 | O4: =IF(C4>0,1+COUNTIFS(O$2:O3,">="&1),0) -> 0 | P4: =IF(D4>0,1+COUNTIFS(P$2:P3,">="&1),0) -> 0 | Q4: =IF(E4>0,1+COUNTIFS(Q$2:Q3,">="&1),0) -> 0 | R4: =IF(F4>0,1+COUNTIFS(R$2:R3,">="&1),0) -> 0 | S4: =IF(G4>0,1+COUNTIFS(S$2:S3,">="&1),0) -> 0 | T4: =IF(H4>0,1+COUNTIFS(T$2:T3,">="&1),0) -> 0 | U4: =IF(I4>0,1+COUNTIFS(U$2:U3,">="&1),0) -> 0 | ... Y4: =IF(M4>0,1+COUNTIFS(Y$2:Y3,">="&1),0) -> 0 | Z4: VARIANCE - VARIMAX - 70% | AB4: 3 | AC4: =IFERROR(INDEX($A$2:$A$30,MATCH(AB4,$N$2:$N$30,0)),"") -> 20 | AD4: =IFERROR(VLOOKUP(AC4,List!$A$1:$B$29,2,FALSE),"") -> When not on my boat, I often find myself doing boating related activities
A5: 16 | B5: 0.63 | N5: =IF(B5>0,1+COUNTIFS(N$2:N4,">="&1),0) -> 4 | O5: =IF(C5>0,1+COUNTIFS(O$2:O4,">="&1),0) -> 0 | P5: =IF(D5>0,1+COUNTIFS(P$2:P4,">="&1),0) -> 0 | Q5: =IF(E5>0,1+COUNTIFS(Q$2:Q4,">="&1),0) -> 0 | R5: =IF(F5>0,1+COUNTIFS(R$2:R4,">="&1),0) -> 0 | S5: =IF(G5>0,1+COUNTIFS(S$2:S4,">="&1),0) -> 0 | T5: =IF(H5>0,1+COUNTIFS(T$2:T4,">="&1),0) -> 0 | U5: =IF(I5>0,1+COUNTIFS(U$2:U4,">="&1),0) -> 0 | ... Y5: =IF(M5>0,1+COUNTIFS(Y$2:Y4,">="&1),0) -> 0 | Z5: VARIANCE - VARIMAX - 70% | AB5: 4 | AC5: =IFERROR(INDEX($A$2:$A$30,MATCH(AB5,$N$2:$N$30,0)),"") -> 16 | AD5: =IFERROR(VLOOKUP(AC5,List!$A$1:$B$29,2,FALSE),"") -> People tend to come to me for advice about boating
A6: 23 | B6: 0.58 | N6: =IF(B6>0,1+COUNTIFS(N$2:N5,">="&1),0) -> 5 | O6: =IF(C6>0,1+COUNTIFS(O$2:O5,">="&1),0) -> 0 | P6: =IF(D6>0,1+COUNTIFS(P$2:P5,">="&1),0) -> 0 | Q6: =IF(E6>0,1+COUNTIFS(Q$2:Q5,">="&1),0) -> 0 | R6: =IF(F6>0,1+COUNTIFS(R$2:R5,">="&1),0) -> 0 | S6: =IF(G6>0,1+COUNTIFS(S$2:S5,">="&1),0) -> 0 | T6: =IF(H6>0,1+COUNTIFS(T$2:T5,">="&1),0) -> 0 | U6: =IF(I6>0,1+COUNTIFS(U$2:U5,">="&1),0) -> 0 | ... Y6: =IF(M6>0,1+COUNTIFS(Y$2:Y5,">="&1),0) -> 0 | Z6: VARIANCE - VARIMAX - 70% | AB6: 5 | AC6: =IFERROR(INDEX($A$2:$A$30,MATCH(AB6,$N$2:$N$30,0)),"") -> 23 | AD6: =IFERROR(VLOOKUP(AC6,List!$A$1:$B$29,2,FALSE),"") -> Boating allows me to excel in the sports that I am passionate about
A7: 17 | B7: 0.56 | N7: =IF(B7>0,1+COUNTIFS(N$2:N6,">="&1),0) -> 6 | O7: =IF(C7>0,1+COUNTIFS(O$2:O6,">="&1),0) -> 0 | P7: =IF(D7>0,1+COUNTIFS(P$2:P6,">="&1),0) -> 0 | Q7: =IF(E7>0,1+COUNTIFS(Q$2:Q6,">="&1),0) -> 0 | R7: =IF(F7>0,1+COUNTIFS(R$2:R6,">="&1),0) -> 0 | S7: =IF(G7>0,1+COUNTIFS(S$2:S6,">="&1),0) -> 0 | T7: =IF(H7>0,1+COUNTIFS(T$2:T6,">="&1),0) -> 0 | U7: =IF(I7>0,1+COUNTIFS(U$2:U6,">="&1),0) -> 0 | ... Y7: =IF(M7>0,1+COUNTIFS(Y$2:Y6,">="&1),0) -> 0 | Z7: VARIANCE - VARIMAX - 70% | AB7: 6 | AC7: =IFERROR(INDEX($A$2:$A$30,MATCH(AB7,$N$2:$N$30,0)),"") -> 17 | AD7: =IFERROR(VLOOKUP(AC7,List!$A$1:$B$29,2,FALSE),"") -> I consider myself more knowledgeable about boating than the rest of my boating peers
A8: 26 | N8: =IF(B8>0,1+COUNTIFS(N$2:N7,">="&1),0) -> 0 | O8: =IF(C8>0,1+COUNTIFS(O$2:O7,">="&1),0) -> 0 | P8: =IF(D8>0,1+COUNTIFS(P$2:P7,">="&1),0) -> 0 | Q8: =IF(E8>0,1+COUNTIFS(Q$2:Q7,">="&1),0) -> 0 | R8: =IF(F8>0,1+COUNTIFS(R$2:R7,">="&1),0) -> 0 | S8: =IF(G8>0,1+COUNTIFS(S$2:S7,">="&1),0) -> 0 | T8: =IF(H8>0,1+COUNTIFS(T$2:T7,">="&1),0) -> 0 | U8: =IF(I8>0,1+COUNTIFS(U$2:U7,">="&1),0) -> 0 | ... Y8: =IF(M8>0,1+COUNTIFS(Y$2:Y7,">="&1),0) -> 0 | Z8: VARIANCE - VARIMAX - 70%
A9: 22 | N9: =IF(B9>0,1+COUNTIFS(N$2:N8,">="&1),0) -> 0 | O9: =IF(C9>0,1+COUNTIFS(O$2:O8,">="&1),0) -> 0 | P9: =IF(D9>0,1+COUNTIFS(P$2:P8,">="&1),0) -> 0 | Q9: =IF(E9>0,1+COUNTIFS(Q$2:Q8,">="&1),0) -> 0 | R9: =IF(F9>0,1+COUNTIFS(R$2:R8,">="&1),0) -> 0 | S9: =IF(G9>0,1+COUNTIFS(S$2:S8,">="&1),0) -> 0 | T9: =IF(H9>0,1+COUNTIFS(T$2:T8,">="&1),0) -> 0 | U9: =IF(I9>0,1+COUNTIFS(U$2:U8,">="&1),0) -> 0 | ... Y9: =IF(M9>0,1+COUNTIFS(Y$2:Y8,">="&1),0) -> 0 | Z9: VARIANCE - VARIMAX - 70% | AC9: Component 2 - Early adopter
A10: 3 | E10: 0.55 | N10: =IF(B10>0,1+COUNTIFS(N$2:N9,">="&1),0) -> 0 | O10: =IF(C10>0,1+COUNTIFS(O$2:O9,">="&1),0) -> 0 | P10: =IF(D10>0,1+COUNTIFS(P$2:P9,">="&1),0) -> 0 | Q10: =IF(E10>0,1+COUNTIFS(Q$2:Q9,">="&1),0) -> 1 | R10: =IF(F10>0,1+COUNTIFS(R$2:R9,">="&1),0) -> 0 | S10: =IF(G10>0,1+COUNTIFS(S$2:S9,">="&1),0) -> 0 | T10: =IF(H10>0,1+COUNTIFS(T$2:T9,">="&1),0) -> 0 | U10: =IF(I10>0,1+COUNTIFS(U$2:U9,">="&1),0) -> 0 | ... Y10: =IF(M10>0,1+COUNTIFS(Y$2:Y9,">="&1),0) -> 0 | Z10: VARIANCE - VARIMAX - 70% | AB10: 1 | AC10: =IFERROR(INDEX($A$2:$A$30,MATCH(AB10,$O$2:$O$30,0)),"") -> 13 | AD10: =IFERROR(VLOOKUP(AC10,List!$A$1:$B$29,2,FALSE),"") -> When buying a boat, I tend to buy the latest and greatest
A11: 9 | E11: 0.64 | N11: =IF(B11>0,1+COUNTIFS(N$2:N10,">="&1),0) -> 0 | O11: =IF(C11>0,1+COUNTIFS(O$2:O10,">="&1),0) -> 0 | P11: =IF(D11>0,1+COUNTIFS(P$2:P10,">="&1),0) -> 0 | Q11: =IF(E11>0,1+COUNTIFS(Q$2:Q10,">="&1),0) -> 2 | R11: =IF(F11>0,1+COUNTIFS(R$2:R10,">="&1),0) -> 0 | S11: =IF(G11>0,1+COUNTIFS(S$2:S10,">="&1),0) -> 0 | T11: =IF(H11>0,1+COUNTIFS(T$2:T10,">="&1),0) -> 0 | U11: =IF(I11>0,1+COUNTIFS(U$2:U10,">="&1),0) -> 0 | ... Y11: =IF(M11>0,1+COUNTIFS(Y$2:Y10,">="&1),0) -> 0 | Z11: VARIANCE - VARIMAX - 70% | AB11: 2 | AC11: =IFERROR(INDEX($A$2:$A$30,MATCH(AB11,$O$2:$O$30,0)),"") -> 14 | AD11: =IFERROR(VLOOKUP(AC11,List!$A$1:$B$29,2,FALSE),"") -> When buying accessories for my boat, I tend to buy the latest and greatest
A12: 13 | C12: 0.75 | N12: =IF(B12>0,1+COUNTIFS(N$2:N11,">="&1),0) -> 0 | O12: =IF(C12>0,1+COUNTIFS(O$2:O11,">="&1),0) -> 1 | P12: =IF(D12>0,1+COUNTIFS(P$2:P11,">="&1),0) -> 0 | Q12: =IF(E12>0,1+COUNTIFS(Q$2:Q11,">="&1),0) -> 0 | R12: =IF(F12>0,1+COUNTIFS(R$2:R11,">="&1),0) -> 0 | S12: =IF(G12>0,1+COUNTIFS(S$2:S11,">="&1),0) -> 0 | T12: =IF(H12>0,1+COUNTIFS(T$2:T11,">="&1),0) -> 0 | U12: =IF(I12>0,1+COUNTIFS(U$2:U11,">="&1),0) -> 0 | ... Y12: =IF(M12>0,1+COUNTIFS(Y$2:Y11,">="&1),0) -> 0 | Z12: VARIANCE - VARIMAX - 70% | AB12: 3 | AC12: =IFERROR(INDEX($A$2:$A$30,MATCH(AB12,$O$2:$O$30,0)),"") -> 15 | AD12: =IFERROR(VLOOKUP(AC12,List!$A$1:$B$29,2,FALSE),"") -> I am serious about the technology on my boat
A13: 14 | C13: 0.75 | N13: =IF(B13>0,1+COUNTIFS(N$2:N12,">="&1),0) -> 0 | O13: =IF(C13>0,1+COUNTIFS(O$2:O12,">="&1),0) -> 2 | P13: =IF(D13>0,1+COUNTIFS(P$2:P12,">="&1),0) -> 0 | Q13: =IF(E13>0,1+COUNTIFS(Q$2:Q12,">="&1),0) -> 0 | R13: =IF(F13>0,1+COUNTIFS(R$2:R12,">="&1),0) -> 0 | S13: =IF(G13>0,1+COUNTIFS(S$2:S12,">="&1),0) -> 0 | T13: =IF(H13>0,1+COUNTIFS(T$2:T12,">="&1),0) -> 0 | U13: =IF(I13>0,1+COUNTIFS(U$2:U12,">="&1),0) -> 0 | ... Y13: =IF(M13>0,1+COUNTIFS(Y$2:Y12,">="&1),0) -> 0 | Z13: VARIANCE - VARIMAX - 70%
A14: 5 | N14: =IF(B14>0,1+COUNTIFS(N$2:N13,">="&1),0) -> 0 | O14: =IF(C14>0,1+COUNTIFS(O$2:O13,">="&1),0) -> 0 | P14: =IF(D14>0,1+COUNTIFS(P$2:P13,">="&1),0) -> 0 | Q14: =IF(E14>0,1+COUNTIFS(Q$2:Q13,">="&1),0) -> 0 | R14: =IF(F14>0,1+COUNTIFS(R$2:R13,">="&1),0) -> 0 | S14: =IF(G14>0,1+COUNTIFS(S$2:S13,">="&1),0) -> 0 | T14: =IF(H14>0,1+COUNTIFS(T$2:T13,">="&1),0) -> 0 | U14: =IF(I14>0,1+COUNTIFS(U$2:U13,">="&1),0) -> 0 | ... Y14: =IF(M14>0,1+COUNTIFS(Y$2:Y13,">="&1),0) -> 0 | Z14: VARIANCE - VARIMAX - 70% | AC14: Component 3 -
A15: 25 | N15: =IF(B15>0,1+COUNTIFS(N$2:N14,">="&1),0) -> 0 | O15: =IF(C15>0,1+COUNTIFS(O$2:O14,">="&1),0) -> 0 | P15: =IF(D15>0,1+COUNTIFS(P$2:P14,">="&1),0) -> 0 | Q15: =IF(E15>0,1+COUNTIFS(Q$2:Q14,">="&1),0) -> 0 | R15: =IF(F15>0,1+COUNTIFS(R$2:R14,">="&1),0) -> 0 | S15: =IF(G15>0,1+COUNTIFS(S$2:S14,">="&1),0) -> 0 | T15: =IF(H15>0,1+COUNTIFS(T$2:T14,">="&1),0) -> 0 | U15: =IF(I15>0,1+COUNTIFS(U$2:U14,">="&1),0) -> 0 | ... Y15: =IF(M15>0,1+COUNTIFS(Y$2:Y14,">="&1),0) -> 0 | Z15: VARIANCE - VARIMAX - 70% | AB15: 1 | AC15: =IFERROR(INDEX($A$2:$A$30,MATCH(AB15,$P$2:$P$30,0)),"") -> 18 | AD15: =IFERROR(VLOOKUP(AC15,List!$A$1:$B$29,2,FALSE),"") -> Boating gives me a feeling of adventure
A16: 15 | C16: 0.63 | N16: =IF(B16>0,1+COUNTIFS(N$2:N15,">="&1),0) -> 0 | O16: =IF(C16>0,1+COUNTIFS(O$2:O15,">="&1),0) -> 3 | P16: =IF(D16>0,1+COUNTIFS(P$2:P15,">="&1),0) -> 0 | Q16: =IF(E16>0,1+COUNTIFS(Q$2:Q15,">="&1),0) -> 0 | R16: =IF(F16>0,1+COUNTIFS(R$2:R15,">="&1),0) -> 0 | S16: =IF(G16>0,1+COUNTIFS(S$2:S15,">="&1),0) -> 0 | T16: =IF(H16>0,1+COUNTIFS(T$2:T15,">="&1),0) -> 0 | U16: =IF(I16>0,1+COUNTIFS(U$2:U15,">="&1),0) -> 0 | ... Y16: =IF(M16>0,1+COUNTIFS(Y$2:Y15,">="&1),0) -> 0 | Z16: VARIANCE - VARIMAX - 70% | AB16: 2 | AC16: =IFERROR(INDEX($A$2:$A$30,MATCH(AB16,$P$2:$P$30,0)),"") -> 21 | AD16: =IFERROR(VLOOKUP(AC16,List!$A$1:$B$29,2,FALSE),"") -> Boating helps me escape from everyday life and relax
A17: 6 | E17: 0.62 | N17: =IF(B17>0,1+COUNTIFS(N$2:N16,">="&1),0) -> 0 | O17: =IF(C17>0,1+COUNTIFS(O$2:O16,">="&1),0) -> 0 | P17: =IF(D17>0,1+COUNTIFS(P$2:P16,">="&1),0) -> 0 | Q17: =IF(E17>0,1+COUNTIFS(Q$2:Q16,">="&1),0) -> 3 | R17: =IF(F17>0,1+COUNTIFS(R$2:R16,">="&1),0) -> 0 | S17: =IF(G17>0,1+COUNTIFS(S$2:S16,">="&1),0) -> 0 | T17: =IF(H17>0,1+COUNTIFS(T$2:T16,">="&1),0) -> 0 | U17: =IF(I17>0,1+COUNTIFS(U$2:U16,">="&1),0) -> 0 | ... Y17: =IF(M17>0,1+COUNTIFS(Y$2:Y16,">="&1),0) -> 0 | Z17: VARIANCE - VARIMAX - 70% | AB17: 3 | AC17: =IFERROR(INDEX($A$2:$A$30,MATCH(AB17,$P$2:$P$30,0)),"") -> 19 | AD17: =IFERROR(VLOOKUP(AC17,List!$A$1:$B$29,2,FALSE),"") -> Boating allows me to experience nature
A18: 7 | E18: 0.74 | N18: =IF(B18>0,1+COUNTIFS(N$2:N17,">="&1),0) -> 0 | O18: =IF(C18>0,1+COUNTIFS(O$2:O17,">="&1),0) -> 0 | P18: =IF(D18>0,1+COUNTIFS(P$2:P17,">="&1),0) -> 0 | Q18: =IF(E18>0,1+COUNTIFS(Q$2:Q17,">="&1),0) -> 4 | R18: =IF(F18>0,1+COUNTIFS(R$2:R17,">="&1),0) -> 0 | S18: =IF(G18>0,1+COUNTIFS(S$2:S17,">="&1),0) -> 0 | T18: =IF(H18>0,1+COUNTIFS(T$2:T17,">="&1),0) -> 0 | U18: =IF(I18>0,1+COUNTIFS(U$2:U17,">="&1),0) -> 0 | ... Y18: =IF(M18>0,1+COUNTIFS(Y$2:Y17,">="&1),0) -> 0 | Z18: VARIANCE - VARIMAX - 70%
A19: 12 | F19: 0.63 | N19: =IF(B19>0,1+COUNTIFS(N$2:N18,">="&1),0) -> 0 | O19: =IF(C19>0,1+COUNTIFS(O$2:O18,">="&1),0) -> 0 | P19: =IF(D19>0,1+COUNTIFS(P$2:P18,">="&1),0) -> 0 | Q19: =IF(E19>0,1+COUNTIFS(Q$2:Q18,">="&1),0) -> 0 | R19: =IF(F19>0,1+COUNTIFS(R$2:R18,">="&1),0) -> 1 | S19: =IF(G19>0,1+COUNTIFS(S$2:S18,">="&1),0) -> 0 | T19: =IF(H19>0,1+COUNTIFS(T$2:T18,">="&1),0) -> 0 | U19: =IF(I19>0,1+COUNTIFS(U$2:U18,">="&1),0) -> 0 | ... Y19: =IF(M19>0,1+COUNTIFS(Y$2:Y18,">="&1),0) -> 0 | Z19: VARIANCE - VARIMAX - 70% | AC19: Component 4
A20: 24 | M20: 0.77 | N20: =IF(B20>0,1+COUNTIFS(N$2:N19,">="&1),0) -> 0 | O20: =IF(C20>0,1+COUNTIFS(O$2:O19,">="&1),0) -> 0 | P20: =IF(D20>0,1+COUNTIFS(P$2:P19,">="&1),0) -> 0 | Q20: =IF(E20>0,1+COUNTIFS(Q$2:Q19,">="&1),0) -> 0 | R20: =IF(F20>0,1+COUNTIFS(R$2:R19,">="&1),0) -> 0 | S20: =IF(G20>0,1+COUNTIFS(S$2:S19,">="&1),0) -> 0 | T20: =IF(H20>0,1+COUNTIFS(T$2:T19,">="&1),0) -> 0 | U20: =IF(I20>0,1+COUNTIFS(U$2:U19,">="&1),0) -> 0 | ... Y20: =IF(M20>0,1+COUNTIFS(Y$2:Y19,">="&1),0) -> 1 | Z20: VARIANCE - VARIMAX - 70% | AB20: 1 | AC20: =IFERROR(INDEX($A$2:$A$30,MATCH(AB20,$Q$2:$Q$30,0)),"") -> 3 | AD20: =IFERROR(VLOOKUP(AC20,List!$A$1:$B$29,2,FALSE),"") -> The brand of the boat I buy says a lot about who I am
A21: 11 | G21: 0.88 | N21: =IF(B21>0,1+COUNTIFS(N$2:N20,">="&1),0) -> 0 | O21: =IF(C21>0,1+COUNTIFS(O$2:O20,">="&1),0) -> 0 | P21: =IF(D21>0,1+COUNTIFS(P$2:P20,">="&1),0) -> 0 | Q21: =IF(E21>0,1+COUNTIFS(Q$2:Q20,">="&1),0) -> 0 | R21: =IF(F21>0,1+COUNTIFS(R$2:R20,">="&1),0) -> 0 | S21: =IF(G21>0,1+COUNTIFS(S$2:S20,">="&1),0) -> 1 | T21: =IF(H21>0,1+COUNTIFS(T$2:T20,">="&1),0) -> 0 | U21: =IF(I21>0,1+COUNTIFS(U$2:U20,">="&1),0) -> 0 | ... Y21: =IF(M21>0,1+COUNTIFS(Y$2:Y20,">="&1),0) -> 0 | Z21: VARIANCE - VARIMAX - 70% | AB21: 2 | AC21: =IFERROR(INDEX($A$2:$A$30,MATCH(AB21,$Q$2:$Q$30,0)),"") -> 9 | AD21: =IFERROR(VLOOKUP(AC21,List!$A$1:$B$29,2,FALSE),"") -> I see my boat as status symbol
A22: 18 | D22: 0.72 | N22: =IF(B22>0,1+COUNTIFS(N$2:N21,">="&1),0) -> 0 | O22: =IF(C22>0,1+COUNTIFS(O$2:O21,">="&1),0) -> 0 | P22: =IF(D22>0,1+COUNTIFS(P$2:P21,">="&1),0) -> 1 | Q22: =IF(E22>0,1+COUNTIFS(Q$2:Q21,">="&1),0) -> 0 | R22: =IF(F22>0,1+COUNTIFS(R$2:R21,">="&1),0) -> 0 | S22: =IF(G22>0,1+COUNTIFS(S$2:S21,">="&1),0) -> 0 | T22: =IF(H22>0,1+COUNTIFS(T$2:T21,">="&1),0) -> 0 | U22: =IF(I22>0,1+COUNTIFS(U$2:U21,">="&1),0) -> 0 | ... Y22: =IF(M22>0,1+COUNTIFS(Y$2:Y21,">="&1),0) -> 0 | Z22: VARIANCE - VARIMAX - 70% | AB22: 3 | AC22: =IFERROR(INDEX($A$2:$A$30,MATCH(AB22,$Q$2:$Q$30,0)),"") -> 6 | AD22: =IFERROR(VLOOKUP(AC22,List!$A$1:$B$29,2,FALSE),"") -> Owning a boat is a way of rewarding myself for hard work
A23: 21 | D23: 0.57 | N23: =IF(B23>0,1+COUNTIFS(N$2:N22,">="&1),0) -> 0 | O23: =IF(C23>0,1+COUNTIFS(O$2:O22,">="&1),0) -> 0 | P23: =IF(D23>0,1+COUNTIFS(P$2:P22,">="&1),0) -> 2 | Q23: =IF(E23>0,1+COUNTIFS(Q$2:Q22,">="&1),0) -> 0 | R23: =IF(F23>0,1+COUNTIFS(R$2:R22,">="&1),0) -> 0 | S23: =IF(G23>0,1+COUNTIFS(S$2:S22,">="&1),0) -> 0 | T23: =IF(H23>0,1+COUNTIFS(T$2:T22,">="&1),0) -> 0 | U23: =IF(I23>0,1+COUNTIFS(U$2:U22,">="&1),0) -> 0 | ... Y23: =IF(M23>0,1+COUNTIFS(Y$2:Y22,">="&1),0) -> 0 | Z23: VARIANCE - VARIMAX - 70% | AB23: 4 | AC23: =IFERROR(INDEX($A$2:$A$30,MATCH(AB23,$Q$2:$Q$30,0)),"") -> 7 | AD23: =IFERROR(VLOOKUP(AC23,List!$A$1:$B$29,2,FALSE),"") -> Owning a boat gives me a sense of achievement
A24: 29 | L24: 0.9 | N24: =IF(B24>0,1+COUNTIFS(N$2:N23,">="&1),0) -> 0 | O24: =IF(C24>0,1+COUNTIFS(O$2:O23,">="&1),0) -> 0 | P24: =IF(D24>0,1+COUNTIFS(P$2:P23,">="&1),0) -> 0 | Q24: =IF(E24>0,1+COUNTIFS(Q$2:Q23,">="&1),0) -> 0 | R24: =IF(F24>0,1+COUNTIFS(R$2:R23,">="&1),0) -> 0 | S24: =IF(G24>0,1+COUNTIFS(S$2:S23,">="&1),0) -> 0 | T24: =IF(H24>0,1+COUNTIFS(T$2:T23,">="&1),0) -> 0 | U24: =IF(I24>0,1+COUNTIFS(U$2:U23,">="&1),0) -> 0 | ... Y24: =IF(M24>0,1+COUNTIFS(Y$2:Y23,">="&1),0) -> 0 | Z24: VARIANCE - VARIMAX - 70%
A25: 1 | K25: 0.94 | N25: =IF(B25>0,1+COUNTIFS(N$2:N24,">="&1),0) -> 0 | O25: =IF(C25>0,1+COUNTIFS(O$2:O24,">="&1),0) -> 0 | P25: =IF(D25>0,1+COUNTIFS(P$2:P24,">="&1),0) -> 0 | Q25: =IF(E25>0,1+COUNTIFS(Q$2:Q24,">="&1),0) -> 0 | R25: =IF(F25>0,1+COUNTIFS(R$2:R24,">="&1),0) -> 0 | S25: =IF(G25>0,1+COUNTIFS(S$2:S24,">="&1),0) -> 0 | T25: =IF(H25>0,1+COUNTIFS(T$2:T24,">="&1),0) -> 0 | U25: =IF(I25>0,1+COUNTIFS(U$2:U24,">="&1),0) -> 0 | ... Y25: =IF(M25>0,1+COUNTIFS(Y$2:Y24,">="&1),0) -> 0 | Z25: VARIANCE - VARIMAX - 70% | AC25: Component 5
A26: 4 | H26: 0.84 | N26: =IF(B26>0,1+COUNTIFS(N$2:N25,">="&1),0) -> 0 | O26: =IF(C26>0,1+COUNTIFS(O$2:O25,">="&1),0) -> 0 | P26: =IF(D26>0,1+COUNTIFS(P$2:P25,">="&1),0) -> 0 | Q26: =IF(E26>0,1+COUNTIFS(Q$2:Q25,">="&1),0) -> 0 | R26: =IF(F26>0,1+COUNTIFS(R$2:R25,">="&1),0) -> 0 | S26: =IF(G26>0,1+COUNTIFS(S$2:S25,">="&1),0) -> 0 | T26: =IF(H26>0,1+COUNTIFS(T$2:T25,">="&1),0) -> 1 | U26: =IF(I26>0,1+COUNTIFS(U$2:U25,">="&1),0) -> 0 | ... Y26: =IF(M26>0,1+COUNTIFS(Y$2:Y25,">="&1),0) -> 0 | Z26: VARIANCE - VARIMAX - 70% | AB26: 1 | AC26: =IFERROR(INDEX($A$2:$A$30,MATCH(AB26,$R$2:$R$30,0)),"") -> 12 | AD26: =IFERROR(VLOOKUP(AC26,List!$A$1:$B$29,2,FALSE),"") -> When it comes to boating, I tend to prefer a basic boat with little to no frills
A27: 19 | D27: 0.83 | N27: =IF(B27>0,1+COUNTIFS(N$2:N26,">="&1),0) -> 0 | O27: =IF(C27>0,1+COUNTIFS(O$2:O26,">="&1),0) -> 0 | P27: =IF(D27>0,1+COUNTIFS(P$2:P26,">="&1),0) -> 3 | Q27: =IF(E27>0,1+COUNTIFS(Q$2:Q26,">="&1),0) -> 0 | R27: =IF(F27>0,1+COUNTIFS(R$2:R26,">="&1),0) -> 0 | S27: =IF(G27>0,1+COUNTIFS(S$2:S26,">="&1),0) -> 0 | T27: =IF(H27>0,1+COUNTIFS(T$2:T26,">="&1),0) -> 0 | U27: =IF(I27>0,1+COUNTIFS(U$2:U26,">="&1),0) -> 0 | ... Y27: =IF(M27>0,1+COUNTIFS(Y$2:Y26,">="&1),0) -> 0 | Z27: VARIANCE - VARIMAX - 70% | AB27: 2 | AC27: =IFERROR(INDEX($A$2:$A$30,MATCH(AB27,$R$2:$R$30,0)),"") -> 2 | AD27: =IFERROR(VLOOKUP(AC27,List!$A$1:$B$29,2,FALSE),"") -> When buying a bot, getting the lowest P is more important than brand
A28: 8 | J28: 0.95 | N28: =IF(B28>0,1+COUNTIFS(N$2:N27,">="&1),0) -> 0 | O28: =IF(C28>0,1+COUNTIFS(O$2:O27,">="&1),0) -> 0 | P28: =IF(D28>0,1+COUNTIFS(P$2:P27,">="&1),0) -> 0 | Q28: =IF(E28>0,1+COUNTIFS(Q$2:Q27,">="&1),0) -> 0 | R28: =IF(F28>0,1+COUNTIFS(R$2:R27,">="&1),0) -> 0 | S28: =IF(G28>0,1+COUNTIFS(S$2:S27,">="&1),0) -> 0 | T28: =IF(H28>0,1+COUNTIFS(T$2:T27,">="&1),0) -> 0 | U28: =IF(I28>0,1+COUNTIFS(U$2:U27,">="&1),0) -> 0 | ... Y28: =IF(M28>0,1+COUNTIFS(Y$2:Y27,">="&1),0) -> 0 | Z28: VARIANCE - VARIMAX - 70%
A29: 2 | F29: 0.83 | N29: =IF(B29>0,1+COUNTIFS(N$2:N28,">="&1),0) -> 0 | O29: =IF(C29>0,1+COUNTIFS(O$2:O28,">="&1),0) -> 0 | P29: =IF(D29>0,1+COUNTIFS(P$2:P28,">="&1),0) -> 0 | Q29: =IF(E29>0,1+COUNTIFS(Q$2:Q28,">="&1),0) -> 0 | R29: =IF(F29>0,1+COUNTIFS(R$2:R28,">="&1),0) -> 2 | S29: =IF(G29>0,1+COUNTIFS(S$2:S28,">="&1),0) -> 0 | T29: =IF(H29>0,1+COUNTIFS(T$2:T28,">="&1),0) -> 0 | U29: =IF(I29>0,1+COUNTIFS(U$2:U28,">="&1),0) -> 0 | ... Y29: =IF(M29>0,1+COUNTIFS(Y$2:Y28,">="&1),0) -> 0 | Z29: VARIANCE - VARIMAX - 70% | AC29: Component 6
A30: 10 | I30: 0.92 | N30: =IF(B30>0,1+COUNTIFS(N$2:N29,">="&1),0) -> 0 | O30: =IF(C30>0,1+COUNTIFS(O$2:O29,">="&1),0) -> 0 | P30: =IF(D30>0,1+COUNTIFS(P$2:P29,">="&1),0) -> 0 | Q30: =IF(E30>0,1+COUNTIFS(Q$2:Q29,">="&1),0) -> 0 | R30: =IF(F30>0,1+COUNTIFS(R$2:R29,">="&1),0) -> 0 | S30: =IF(G30>0,1+COUNTIFS(S$2:S29,">="&1),0) -> 0 | T30: =IF(H30>0,1+COUNTIFS(T$2:T29,">="&1),0) -> 0 | U30: =IF(I30>0,1+COUNTIFS(U$2:U29,">="&1),0) -> 1 | ... Y30: =IF(M30>0,1+COUNTIFS(Y$2:Y29,">="&1),0) -> 0 | Z30: VARIANCE - VARIMAX - 70% | AB30: 1 | AC30: =IFERROR(INDEX($A$2:$A$30,MATCH(AB30,$S$2:$S$30,0)),"") -> 11 | AD30: =IFERROR(VLOOKUP(AC30,List!$A$1:$B$29,2,FALSE),"") -> I tend to perform minor boat repairs and maintenance on my own
AC32: Component 7
AB33: 1 | AC33: =IFERROR(INDEX($A$2:$A$30,MATCH(AB33,$T$2:$T$30,0)),"") -> 4 | AD33: =IFERROR(VLOOKUP(AC33,List!$A$1:$B$29,2,FALSE),"") -> I only consider buying a boat from a reputable brand
AC35: Component 8
AB36: 1 | AC36: =IFERROR(INDEX($A$2:$A$30,MATCH(AB36,$U$2:$U$30,0)),"") -> 10 | AD36: =IFERROR(VLOOKUP(AC36,List!$A$1:$B$29,2,FALSE),"") -> When buying a boat, I rely more on expert opinion than my own
AC38: Component 9
AB39: 1 | AC39: =IFERROR(INDEX($A$2:$A$30,MATCH(AB39,$V$2:$V$30,0)),"") -> 8 | AD39: =IFERROR(VLOOKUP(AC39,List!$A$1:$B$29,2,FALSE),"") -> When buying a boat, functionality is more important than style
AC41: Component 10
AB42: 1 | AC42: =IFERROR(INDEX($A$2:$A$30,MATCH(AB42,$W$2:$W$30,0)),"") -> 1 | AD42: =IFERROR(VLOOKUP(AC42,List!$A$1:$B$29,2,FALSE),"") -> When buying a boat, I do a lot of shopping around and visit multiple dealers
AC44: Component 11
AB45: 1 | AC45: =IFERROR(INDEX($A$2:$A$30,MATCH(AB45,$X$2:$X$30,0)),"") -> 29 | AD45: =IFERROR(VLOOKUP(AC45,List!$A$1:$B$29,2,FALSE),"") -> Boating is one of many things I do in my spare time
...
