Workbook

Sheet Eigenvalue varimax
B1: Component 1 - Early birds/crazy about boats/ experts
A2: 9 | B2: =+VLOOKUP(A2,List!$A$1:$B$29,2,FALSE) -> I see my boat as status symbol
A3: 26 | B3: =+VLOOKUP(A3,List!$A$1:$B$29,2,FALSE) -> Having a powerful boat is what is most important to me
A4: 3 | B4: =+VLOOKUP(A4,List!$A$1:$B$29,2,FALSE) -> The brand of the boat I buy says a lot about who I am
A5: 13 | B5: =+VLOOKUP(A5,List!$A$1:$B$29,2,FALSE) -> When buying a boat, I tend to buy the latest and greatest
A6: 27 | B6: =+VLOOKUP(A6,List!$A$1:$B$29,2,FALSE) -> Boating is the number one thing I do with my spare time
A7: 28 | B7: =+VLOOKUP(A7,List!$A$1:$B$29,2,FALSE) -> Boating is my true passion in life
A8: 14 | B8: =+VLOOKUP(A8,List!$A$1:$B$29,2,FALSE) -> When buying accessories for my boat, I tend to buy the latest and greatest
A9: 16 | B9: =+VLOOKUP(A9,List!$A$1:$B$29,2,FALSE) -> People tend to come to me for advice about boating
A10: 7 | B10: =+VLOOKUP(A10,List!$A$1:$B$29,2,FALSE) -> Owning a boat gives me a sense of achievement
A11: 17 | B11: =+VLOOKUP(A11,List!$A$1:$B$29,2,FALSE) -> I consider myself more knowledgeable about boating than the rest of my boating peers
A12: 20 | B12: =+VLOOKUP(A12,List!$A$1:$B$29,2,FALSE) -> When not on my boat, I often find myself doing boating related activities
B15: Component 2 - Getting away with boat
A16: 7 | B16: =+VLOOKUP(A16,List!$A$1:$B$29,2,FALSE) -> Owning a boat gives me a sense of achievement
A17: 6 | B17: =+VLOOKUP(A17,List!$A$1:$B$29,2,FALSE) -> Owning a boat is a way of rewarding myself for hard work
A18: 22 | B18: =+VLOOKUP(A18,List!$A$1:$B$29,2,FALSE) -> Boating helps me stay active
A19: 18 | B19: =+VLOOKUP(A19,List!$A$1:$B$29,2,FALSE) -> Boating gives me a feeling of adventure
A20: 24 | B20: =+VLOOKUP(A20,List!$A$1:$B$29,2,FALSE) -> Boating gives me an outlet to socialize with family/friends
A21: 21 | B21: =+VLOOKUP(A21,List!$A$1:$B$29,2,FALSE) -> Boating helps me escape from everyday life and relax
A22: 19 | B22: =+VLOOKUP(A22,List!$A$1:$B$29,2,FALSE) -> Boating allows me to experience nature
B25: Component 3 - brand lovers
A26: 5 | B26: =+VLOOKUP(A26,List!$A$1:$B$29,2,FALSE) -> I am willing to pay a premium for a brand with a reputation for high quality
A27: 15 | B27: =+VLOOKUP(A27,List!$A$1:$B$29,2,FALSE) -> I am serious about the technology on my boat
A28: 4 | B28: =+VLOOKUP(A28,List!$A$1:$B$29,2,FALSE) -> I only consider buying a boat from a reputable brand
B31: Component 4 - Experts
A32: 16 | B32: =+VLOOKUP(A32,List!$A$1:$B$29,2,FALSE) -> People tend to come to me for advice about boating
A33: 17 | B33: =+VLOOKUP(A33,List!$A$1:$B$29,2,FALSE) -> I consider myself more knowledgeable about boating than the rest of my boating peers
A34: 11 | B34: =+VLOOKUP(A34,List!$A$1:$B$29,2,FALSE) -> I tend to perform minor boat repairs and maintenance on my own
B37: Component 5 - Price conscious
A38: 2 | B38: =+VLOOKUP(A38,List!$A$1:$B$29,2,FALSE) -> When buying a bot, getting the lowest P is more important than brand
A39: 12 | B39: =+VLOOKUP(A39,List!$A$1:$B$29,2,FALSE) -> When it comes to boating, I tend to prefer a basic boat with little to no frills
A40: 8 | B40: =+VLOOKUP(A40,List!$A$1:$B$29,2,FALSE) -> When buying a boat, functionality is more important than style

Sheet Eigenvalue quatimax
B1: Component 1 -
A2: 28 | B2: =+VLOOKUP(A2,List!$A$1:$B$29,2,FALSE) -> Boating is my true passion in life
A3: 14 | B3: =+VLOOKUP(A3,List!$A$1:$B$29,2,FALSE) -> When buying accessories for my boat, I tend to buy the latest and greatest
A4: 20 | B4: =+VLOOKUP(A4,List!$A$1:$B$29,2,FALSE) -> When not on my boat, I often find myself doing boating related activities
A5: 27 | B5: =+VLOOKUP(A5,List!$A$1:$B$29,2,FALSE) -> Boating is the number one thing I do with my spare time
A6: 3 | B6: =+VLOOKUP(A6,List!$A$1:$B$29,2,FALSE) -> The brand of the boat I buy says a lot about who I am
A7: 7 | B7: =+VLOOKUP(A7,List!$A$1:$B$29,2,FALSE) -> Owning a boat gives me a sense of achievement
A8: 15 | B8: =+VLOOKUP(A8,List!$A$1:$B$29,2,FALSE) -> I am serious about the technology on my boat
A9: 16 | B9: =+VLOOKUP(A9,List!$A$1:$B$29,2,FALSE) -> People tend to come to me for advice about boating
A10: 13 | B10: =+VLOOKUP(A10,List!$A$1:$B$29,2,FALSE) -> When buying a boat, I tend to buy the latest and greatest
A11: 25 | B11: =+VLOOKUP(A11,List!$A$1:$B$29,2,FALSE) -> Being in charge of my boat is what is most important to me
A12: 6 | B12: =+VLOOKUP(A12,List!$A$1:$B$29,2,FALSE) -> Owning a boat is a way of rewarding myself for hard work
A13: 26 | B13: =+VLOOKUP(A13,List!$A$1:$B$29,2,FALSE) -> Having a powerful boat is what is most important to me
... A19: 18 | B19: =+VLOOKUP(A19,List!$A$1:$B$29,2,FALSE) -> Boating gives me a feeling of adventure
B22: Component 2 - Getting away with boat
A23: 21 | B23: =+VLOOKUP(A23,List!$A$1:$B$29,2,FALSE) -> Boating helps me escape from everyday life and relax
A24: 19 | B24: =+VLOOKUP(A24,List!$A$1:$B$29,2,FALSE) -> Boating allows me to experience nature
B27: Component 3 - price conscious
A28: 8 | B28: =+VLOOKUP(A28,List!$A$1:$B$29,2,FALSE) -> When buying a boat, functionality is more important than style
A29: 2 | B29: =+VLOOKUP(A29,List!$A$1:$B$29,2,FALSE) -> When buying a bot, getting the lowest P is more important than brand
A30: 12 | B30: =+VLOOKUP(A30,List!$A$1:$B$29,2,FALSE) -> When it comes to boating, I tend to prefer a basic boat with little to no frills
B33: Component 4 -
A34: 11 | B34: =+VLOOKUP(A34,List!$A$1:$B$29,2,FALSE) -> I tend to perform minor boat repairs and maintenance on my own
A35: 10 | B35: =+VLOOKUP(A35,List!$A$1:$B$29,2,FALSE) -> When buying a boat, I rely more on expert opinion than my own

Sheet Eigenvalue proxmax
B1: Component 1 -
A2: 9 | B2: =+VLOOKUP(A2,List!$A$1:$B$29,2,FALSE) -> I see my boat as status symbol
A3: 26 | B3: =+VLOOKUP(A3,List!$A$1:$B$29,2,FALSE) -> Having a powerful boat is what is most important to me
A4: 3 | B4: =+VLOOKUP(A4,List!$A$1:$B$29,2,FALSE) -> The brand of the boat I buy says a lot about who I am
A5: 13 | B5: =+VLOOKUP(A5,List!$A$1:$B$29,2,FALSE) -> When buying a boat, I tend to buy the latest and greatest
A6: 27 | B6: =+VLOOKUP(A6,List!$A$1:$B$29,2,FALSE) -> Boating is the number one thing I do with my spare time
A7: 14 | B7: =+VLOOKUP(A7,List!$A$1:$B$29,2,FALSE) -> When buying accessories for my boat, I tend to buy the latest and greatest
A8: 28 | B8: =+VLOOKUP(A8,List!$A$1:$B$29,2,FALSE) -> Boating is my true passion in life
A9: 7 | B9: =+VLOOKUP(A9,List!$A$1:$B$29,2,FALSE) -> Owning a boat gives me a sense of achievement
B12: Component 2 - Getting away with boat
A13: 7 | B13: =+VLOOKUP(A13,List!$A$1:$B$29,2,FALSE) -> Owning a boat gives me a sense of achievement
A14: 6 | B14: =+VLOOKUP(A14,List!$A$1:$B$29,2,FALSE) -> Owning a boat is a way of rewarding myself for hard work
A15: 22 | B15: =+VLOOKUP(A15,List!$A$1:$B$29,2,FALSE) -> Boating helps me stay active
A16: 24 | B16: =+VLOOKUP(A16,List!$A$1:$B$29,2,FALSE) -> Boating gives me an outlet to socialize with family/friends
A17: 18 | B17: =+VLOOKUP(A17,List!$A$1:$B$29,2,FALSE) -> Boating gives me a feeling of adventure
A18: 21 | B18: =+VLOOKUP(A18,List!$A$1:$B$29,2,FALSE) -> Boating helps me escape from everyday life and relax
A19: 19 | B19: =+VLOOKUP(A19,List!$A$1:$B$29,2,FALSE) -> Boating allows me to experience nature
B22: Component 3 -
A23: 16 | B23: =+VLOOKUP(A23,List!$A$1:$B$29,2,FALSE) -> People tend to come to me for advice about boating
A24: 17 | B24: =+VLOOKUP(A24,List!$A$1:$B$29,2,FALSE) -> I consider myself more knowledgeable about boating than the rest of my boating peers
A25: 10 | B25: =+VLOOKUP(A25,List!$A$1:$B$29,2,FALSE) -> When buying a boat, I rely more on expert opinion than my own
A26: 11 | B26: =+VLOOKUP(A26,List!$A$1:$B$29,2,FALSE) -> I tend to perform minor boat repairs and maintenance on my own
B30: Component 4 - Brand/Quality
A31: 5 | B31: =+VLOOKUP(A31,List!$A$1:$B$29,2,FALSE) -> I am willing to pay a premium for a brand with a reputation for high quality
A32: 4 | B32: =+VLOOKUP(A32,List!$A$1:$B$29,2,FALSE) -> I only consider buying a boat from a reputable brand
B35: Component 5 - Price conscious
A36: 2 | B36: =+VLOOKUP(A36,List!$A$1:$B$29,2,FALSE) -> When buying a bot, getting the lowest P is more important than brand
A37: 10 | B37: =+VLOOKUP(A37,List!$A$1:$B$29,2,FALSE) -> When buying a boat, I rely more on expert opinion than my own
A38: 12 | B38: =+VLOOKUP(A38,List!$A$1:$B$29,2,FALSE) -> When it comes to boating, I tend to prefer a basic boat with little to no frills
A39: 8 | B39: =+VLOOKUP(A39,List!$A$1:$B$29,2,FALSE) -> When buying a boat, functionality is more important than style

Sheet Eigenvalue oblimin
B1: Component 1 - Getting away with boat
A2: 21 | B2: =+VLOOKUP(A2,List!$A$1:$B$29,2,FALSE) -> Boating helps me escape from everyday life and relax
A3: 18 | B3: =+VLOOKUP(A3,List!$A$1:$B$29,2,FALSE) -> Boating gives me a feeling of adventure
A4: 19 | B4: =+VLOOKUP(A4,List!$A$1:$B$29,2,FALSE) -> Boating allows me to experience nature
A5: 6 | B5: =+VLOOKUP(A5,List!$A$1:$B$29,2,FALSE) -> Owning a boat is a way of rewarding myself for hard work
A6: 24 | B6: =+VLOOKUP(A6,List!$A$1:$B$29,2,FALSE) -> Boating gives me an outlet to socialize with family/friends
A7: 22 | B7: =+VLOOKUP(A7,List!$A$1:$B$29,2,FALSE) -> Boating helps me stay active
A8: 7 | B8: =+VLOOKUP(A8,List!$A$1:$B$29,2,FALSE) -> Owning a boat gives me a sense of achievement
B11: Component 2 - Expert
A12: 11 | B12: =+VLOOKUP(A12,List!$A$1:$B$29,2,FALSE) -> I tend to perform minor boat repairs and maintenance on my own
A13: 16 | B13: =+VLOOKUP(A13,List!$A$1:$B$29,2,FALSE) -> People tend to come to me for advice about boating
A14: 17 | B14: =+VLOOKUP(A14,List!$A$1:$B$29,2,FALSE) -> I consider myself more knowledgeable about boating than the rest of my boating peers
B17: Component 3 - High quality + brand
A18: 15 | B18: =+VLOOKUP(A18,List!$A$1:$B$29,2,FALSE) -> I am serious about the technology on my boat
A19: 4 | B19: =+VLOOKUP(A19,List!$A$1:$B$29,2,FALSE) -> I only consider buying a boat from a reputable brand
A20: 5 | B20: =+VLOOKUP(A20,List!$A$1:$B$29,2,FALSE) -> I am willing to pay a premium for a brand with a reputation for high quality
A21: 14 | B21: =+VLOOKUP(A21,List!$A$1:$B$29,2,FALSE) -> When buying accessories for my boat, I tend to buy the latest and greatest
A22: 13 | B22: =+VLOOKUP(A22,List!$A$1:$B$29,2,FALSE) -> When buying a boat, I tend to buy the latest and greatest
B25: Component 4 - Status
A26: 3 | B26: =+VLOOKUP(A26,List!$A$1:$B$29,2,FALSE) -> The brand of the boat I buy says a lot about who I am
A27: 9 | B27: =+VLOOKUP(A27,List!$A$1:$B$29,2,FALSE) -> I see my boat as status symbol
A28: 26 | B28: =+VLOOKUP(A28,List!$A$1:$B$29,2,FALSE) -> Having a powerful boat is what is most important to me
B31: Component 5 - Price conscious
A32: 10 | B32: =+VLOOKUP(A32,List!$A$1:$B$29,2,FALSE) -> When buying a boat, I rely more on expert opinion than my own
A33: 8 | B33: =+VLOOKUP(A33,List!$A$1:$B$29,2,FALSE) -> When buying a boat, functionality is more important than style
A34: 2 | B34: =+VLOOKUP(A34,List!$A$1:$B$29,2,FALSE) -> When buying a bot, getting the lowest P is more important than brand
A35: 12 | B35: =+VLOOKUP(A35,List!$A$1:$B$29,2,FALSE) -> When it comes to boating, I tend to prefer a basic boat with little to no frills

Sheet Eigenvalue simplimax
B1: Component 1 -
A2: 28 | B2: =+VLOOKUP(A2,List!$A$1:$B$29,2,FALSE) -> Boating is my true passion in life
A3: 27 | B3: =+VLOOKUP(A3,List!$A$1:$B$29,2,FALSE) -> Boating is the number one thing I do with my spare time
A4: 20 | B4: =+VLOOKUP(A4,List!$A$1:$B$29,2,FALSE) -> When not on my boat, I often find myself doing boating related activities
A5: 3 | B5: =+VLOOKUP(A5,List!$A$1:$B$29,2,FALSE) -> The brand of the boat I buy says a lot about who I am
A6: 16 | B6: =+VLOOKUP(A6,List!$A$1:$B$29,2,FALSE) -> People tend to come to me for advice about boating
A7: 7 | B7: =+VLOOKUP(A7,List!$A$1:$B$29,2,FALSE) -> Owning a boat gives me a sense of achievement
A8: 9 | B8: =+VLOOKUP(A8,List!$A$1:$B$29,2,FALSE) -> I see my boat as status symbol
A9: 14 | B9: =+VLOOKUP(A9,List!$A$1:$B$29,2,FALSE) -> When buying accessories for my boat, I tend to buy the latest and greatest
A10: 26 | B10: =+VLOOKUP(A10,List!$A$1:$B$29,2,FALSE) -> Having a powerful boat is what is most important to me
A11: 13 | B11: =+VLOOKUP(A11,List!$A$1:$B$29,2,FALSE) -> When buying a boat, I tend to buy the latest and greatest
A12: 17 | B12: =+VLOOKUP(A12,List!$A$1:$B$29,2,FALSE) -> I consider myself more knowledgeable about boating than the rest of my boating peers
A13: 15 | B13: =+VLOOKUP(A13,List!$A$1:$B$29,2,FALSE) -> I am serious about the technology on my boat
... A19: 18 | B19: =+VLOOKUP(A19,List!$A$1:$B$29,2,FALSE) -> Boating gives me a feeling of adventure
B22: Component 2 - Getting away with boat
A23: 18 | B23: =+VLOOKUP(A23,List!$A$1:$B$29,2,FALSE) -> Boating gives me a feeling of adventure
A24: 21 | B24: =+VLOOKUP(A24,List!$A$1:$B$29,2,FALSE) -> Boating helps me escape from everyday life and relax
A25: 19 | B25: =+VLOOKUP(A25,List!$A$1:$B$29,2,FALSE) -> Boating allows me to experience nature
B28: Component 3 - price conscious
A29: 2 | B29: =+VLOOKUP(A29,List!$A$1:$B$29,2,FALSE) -> When buying a bot, getting the lowest P is more important than brand
A30: 12 | B30: =+VLOOKUP(A30,List!$A$1:$B$29,2,FALSE) -> When it comes to boating, I tend to prefer a basic boat with little to no frills
B33: Component 4 -
A34: 10 | B34: =+VLOOKUP(A34,List!$A$1:$B$29,2,FALSE) -> When buying a boat, I rely more on expert opinion than my own
B36: Component 5 -
A37: 4 | B37: =+VLOOKUP(A37,List!$A$1:$B$29,2,FALSE) -> I only consider buying a boat from a reputable brand

Sheet Eigenvalue cluster
B1: Component 1 -
A2: 9 | B2: =+VLOOKUP(A2,List!$A$1:$B$29,2,FALSE) -> I see my boat as status symbol
A3: 26 | B3: =+VLOOKUP(A3,List!$A$1:$B$29,2,FALSE) -> Having a powerful boat is what is most important to me
A4: 16 | B4: =+VLOOKUP(A4,List!$A$1:$B$29,2,FALSE) -> People tend to come to me for advice about boating
A5: 27 | B5: =+VLOOKUP(A5,List!$A$1:$B$29,2,FALSE) -> Boating is the number one thing I do with my spare time
A6: 3 | B6: =+VLOOKUP(A6,List!$A$1:$B$29,2,FALSE) -> The brand of the boat I buy says a lot about who I am
A7: 17 | B7: =+VLOOKUP(A7,List!$A$1:$B$29,2,FALSE) -> I consider myself more knowledgeable about boating than the rest of my boating peers
A8: 28 | B8: =+VLOOKUP(A8,List!$A$1:$B$29,2,FALSE) -> Boating is my true passion in life
A9: 13 | B9: =+VLOOKUP(A9,List!$A$1:$B$29,2,FALSE) -> When buying a boat, I tend to buy the latest and greatest
A10: 20 | B10: =+VLOOKUP(A10,List!$A$1:$B$29,2,FALSE) -> When not on my boat, I often find myself doing boating related activities
A11: 14 | B11: =+VLOOKUP(A11,List!$A$1:$B$29,2,FALSE) -> When buying accessories for my boat, I tend to buy the latest and greatest
A12: 7 | B12: =+VLOOKUP(A12,List!$A$1:$B$29,2,FALSE) -> Owning a boat gives me a sense of achievement
B15: Component 2 - Getting away with boat
A16: 6 | B16: =+VLOOKUP(A16,List!$A$1:$B$29,2,FALSE) -> Owning a boat is a way of rewarding myself for hard work
A17: 22 | B17: =+VLOOKUP(A17,List!$A$1:$B$29,2,FALSE) -> Boating helps me stay active
A18: 18 | B18: =+VLOOKUP(A18,List!$A$1:$B$29,2,FALSE) -> Boating gives me a feeling of adventure
A19: 24 | B19: =+VLOOKUP(A19,List!$A$1:$B$29,2,FALSE) -> Boating gives me an outlet to socialize with family/friends
A20: 21 | B20: =+VLOOKUP(A20,List!$A$1:$B$29,2,FALSE) -> Boating helps me escape from everyday life and relax
A21: 19 | B21: =+VLOOKUP(A21,List!$A$1:$B$29,2,FALSE) -> Boating allows me to experience nature
B24: Component 3 - Brand
A25: 5 | B25: =+VLOOKUP(A25,List!$A$1:$B$29,2,FALSE) -> I am willing to pay a premium for a brand with a reputation for high quality
A26: 4 | B26: =+VLOOKUP(A26,List!$A$1:$B$29,2,FALSE) -> I only consider buying a boat from a reputable brand
B29: Component 4 - Price conscious
A30: 2 | B30: =+VLOOKUP(A30,List!$A$1:$B$29,2,FALSE) -> When buying a bot, getting the lowest P is more important than brand
A31: 12 | B31: =+VLOOKUP(A31,List!$A$1:$B$29,2,FALSE) -> When it comes to boating, I tend to prefer a basic boat with little to no frills
A32: 8 | B32: =+VLOOKUP(A32,List!$A$1:$B$29,2,FALSE) -> When buying a boat, functionality is more important than style
B35: Component 5 - Expertise
A36: 11 | B36: =+VLOOKUP(A36,List!$A$1:$B$29,2,FALSE) -> I tend to perform minor boat repairs and maintenance on my own
A37: 10 | B37: =+VLOOKUP(A37,List!$A$1:$B$29,2,FALSE) -> When buying a boat, I rely more on expert opinion than my own

Sheet Eigenvalue none
B1: Component 1 -
A2: 28 | B2: =+VLOOKUP(A2,List!$A$1:$B$29,2,FALSE) -> Boating is my true passion in life
A3: 14 | B3: =+VLOOKUP(A3,List!$A$1:$B$29,2,FALSE) -> When buying accessories for my boat, I tend to buy the latest and greatest
A4: 20 | B4: =+VLOOKUP(A4,List!$A$1:$B$29,2,FALSE) -> When not on my boat, I often find myself doing boating related activities
A5: 27 | B5: =+VLOOKUP(A5,List!$A$1:$B$29,2,FALSE) -> Boating is the number one thing I do with my spare time
A6: 3 | B6: =+VLOOKUP(A6,List!$A$1:$B$29,2,FALSE) -> The brand of the boat I buy says a lot about who I am
A7: 7 | B7: =+VLOOKUP(A7,List!$A$1:$B$29,2,FALSE) -> Owning a boat gives me a sense of achievement
A8: 15 | B8: =+VLOOKUP(A8,List!$A$1:$B$29,2,FALSE) -> I am serious about the technology on my boat
A9: 16 | B9: =+VLOOKUP(A9,List!$A$1:$B$29,2,FALSE) -> People tend to come to me for advice about boating
A10: 13 | B10: =+VLOOKUP(A10,List!$A$1:$B$29,2,FALSE) -> When buying a boat, I tend to buy the latest and greatest
A11: 25 | B11: =+VLOOKUP(A11,List!$A$1:$B$29,2,FALSE) -> Being in charge of my boat is what is most important to me
A12: 6 | B12: =+VLOOKUP(A12,List!$A$1:$B$29,2,FALSE) -> Owning a boat is a way of rewarding myself for hard work
A13: 26 | B13: =+VLOOKUP(A13,List!$A$1:$B$29,2,FALSE) -> Having a powerful boat is what is most important to me
... A19: 18 | B19: =+VLOOKUP(A19,List!$A$1:$B$29,2,FALSE) -> Boating gives me a feeling of adventure
B22: Component 2 - Getting away with boat
A23: 21 | B23: =+VLOOKUP(A23,List!$A$1:$B$29,2,FALSE) -> Boating helps me escape from everyday life and relax
A24: 19 | B24: =+VLOOKUP(A24,List!$A$1:$B$29,2,FALSE) -> Boating allows me to experience nature
B27: Component 3 - Price conscious
A28: 8 | B28: =+VLOOKUP(A28,List!$A$1:$B$29,2,FALSE) -> When buying a boat, functionality is more important than style
A29: 2 | B29: =+VLOOKUP(A29,List!$A$1:$B$29,2,FALSE) -> When buying a bot, getting the lowest P is more important than brand
A30: 13 | B30: =+VLOOKUP(A30,List!$A$1:$B$29,2,FALSE) -> When buying a boat, I tend to buy the latest and greatest
B33: Component 4 - Expertise
A34: 11 | B34: =+VLOOKUP(A34,List!$A$1:$B$29,2,FALSE) -> I tend to perform minor boat repairs and maintenance on my own
A35: 10 | B35: =+VLOOKUP(A35,List!$A$1:$B$29,2,FALSE) -> When buying a boat, I rely more on expert opinion than my own

Sheet Sheet2
A3: METHOD | B3: QUESTION | C3: Sum of RANKComp.1 | D3: Sum of RANKComp.2 | E3: Sum of RANKComp.3 | F3: Sum of RANKComp.4 | G3: Sum of RANKComp.5 | H3: Sum of RANKComp.6 | I3: Sum of RANKComp.7 | J3: Sum of RANKComp.8 | K3: Sum of RANKComp.9 | L3: Sum of RANKComp.10 | M3: Sum of RANKComp.11 | N3: Sum of RANKComp.12
A4: VARIANCE - VARIMAX - 70% | B4: 1 | C4: 0 | D4: 0 | E4: 0 | F4: 0 | G4: 0 | H4: 0 | I4: 0 | J4: 0 | K4: 0 | L4: 1 | M4: 0 | N4: 0
A5: VARIANCE - VARIMAX - 70% | B5: 2 | C5: 0 | D5: 0 | E5: 0 | F5: 0 | G5: 2 | H5: 0 | I5: 0 | J5: 0 | K5: 0 | L5: 0 | M5: 0 | N5: 0
A6: VARIANCE - VARIMAX - 70% | B6: 3 | C6: 0 | D6: 0 | E6: 0 | F6: 1 | G6: 0 | H6: 0 | I6: 0 | J6: 0 | K6: 0 | L6: 0 | M6: 0 | N6: 0
A7: VARIANCE - VARIMAX - 70% | B7: 4 | C7: 0 | D7: 0 | E7: 0 | F7: 0 | G7: 0 | H7: 0 | I7: 1 | J7: 0 | K7: 0 | L7: 0 | M7: 0 | N7: 0
A8: VARIANCE - VARIMAX - 70% | B8: 5 | C8: 0 | D8: 0 | E8: 0 | F8: 0 | G8: 0 | H8: 0 | I8: 0 | J8: 0 | K8: 0 | L8: 0 | M8: 0 | N8: 0
A9: VARIANCE - VARIMAX - 70% | B9: 6 | C9: 0 | D9: 0 | E9: 0 | F9: 3 | G9: 0 | H9: 0 | I9: 0 | J9: 0 | K9: 0 | L9: 0 | M9: 0 | N9: 0
A10: VARIANCE - VARIMAX - 70% | B10: 7 | C10: 0 | D10: 0 | E10: 0 | F10: 4 | G10: 0 | H10: 0 | I10: 0 | J10: 0 | K10: 0 | L10: 0 | M10: 0 | N10: 0
A11: VARIANCE - VARIMAX - 70% | B11: 8 | C11: 0 | D11: 0 | E11: 0 | F11: 0 | G11: 0 | H11: 0 | I11: 0 | J11: 0 | K11: 1 | L11: 0 | M11: 0 | N11: 0
A12: VARIANCE - VARIMAX - 70% | B12: 9 | C12: 0 | D12: 0 | E12: 0 | F12: 2 | G12: 0 | H12: 0 | I12: 0 | J12: 0 | K12: 0 | L12: 0 | M12: 0 | N12: 0
A13: VARIANCE - VARIMAX - 70% | B13: 10 | C13: 0 | D13: 0 | E13: 0 | F13: 0 | G13: 0 | H13: 0 | I13: 0 | J13: 1 | K13: 0 | L13: 0 | M13: 0 | N13: 0
A14: VARIANCE - VARIMAX - 70% | B14: 11 | C14: 0 | D14: 0 | E14: 0 | F14: 0 | G14: 0 | H14: 1 | I14: 0 | J14: 0 | K14: 0 | L14: 0 | M14: 0 | N14: 0
A15: VARIANCE - VARIMAX - 70% | B15: 12 | C15: 0 | D15: 0 | E15: 0 | F15: 0 | G15: 1 | H15: 0 | I15: 0 | J15: 0 | K15: 0 | L15: 0 | M15: 0 | N15: 0
... A32: VARIANCE - VARIMAX - 70% | B32: 29 | C32: 0 | D32: 0 | E32: 0 | F32: 0 | G32: 0 | H32: 0 | I32: 0 | J32: 0 | K32: 0 | L32: 0 | M32: 1 | N32: 0
A33: Grand Total | C33: 21 | D33: 6 | E33: 6 | F33: 10 | G33: 3 | H33: 1 | I33: 1 | J33: 1 | K33: 1 | L33: 1 | M33: 1 | N33: 1

Sheet Variance - 70%
A1: VARIMAX | D1: c(28,14,20,8,3,12,5,11,9,2,30,25) | N1: 1 | O1: 2 | P1: 3 | Q1: 4 | R1: 5 | S1: 5 | T1: 4 | U1: 6 | V1: 5 | W1: 5 | X1: 7 | Y1: 3
A2: QUESTION | B2: Comp.1 | C2: Comp.2 | D2: Comp.3 | E2: Comp.4 | F2: Comp.5 | G2: Comp.6 | H2: Comp.7 | I2: Comp.8 | J2: Comp.9 | K2: Comp.10 | L2: Comp.11 | M2: Comp.12 | N2: Boat Enthusiast? | O2: Early adopter? | P2: Adventurer? | Q2: Do you value Status? | R2: Cheapo? | S2: DIY | T2: Brand aware | U2: Do you rely on expert opinion? | V2: Possibly cheapo of geek | W2: Cheapo possibly or deal hunter | X2: RANKComp.11 | Y2: Blend with adventurer and call the guy "escaper from routine"
A3: 27 | B3: 0.76 | C3: NA | D3: NA | E3: NA | F3: NA | G3: NA | H3: NA | I3: NA | J3: NA | K3: NA | L3: NA | M3: NA | N3: =IF(IF(ISNUMBER(B3),VLOOKUP($A3,List!$A$1:$B$29,2,FALSE))=FALSE,"",IF(ISNUMBER(B3),VLOOKUP($A3,List!$A$1:$B$29,2,FALSE))) -> Boating is the number one thing I do with my spare time | O3: =IF(IF(ISNUMBER(C3),VLOOKUP($A3,List!$A$1:$B$29,2,FALSE))=FALSE,"",IF(ISNUMBER(C3),VLOOKUP($A3,List!$A$1:$B$29,2,FALSE))) | P3: =IF(IF(ISNUMBER(D3),VLOOKUP($A3,List!$A$1:$B$29,2,FALSE))=FALSE,"",IF(ISNUMBER(D3),VLOOKUP($A3,List!$A$1:$B$29,2,FALSE))) | Q3: =IF(IF(ISNUMBER(E3),VLOOKUP($A3,List!$A$1:$B$29,2,FALSE))=FALSE,"",IF(ISNUMBER(E3),VLOOKUP($A3,List!$A$1:$B$29,2,FALSE))) | R3: =IF(IF(ISNUMBER(F3),VLOOKUP($A3,List!$A$1:$B$29,2,FALSE))=FALSE,"",IF(ISNUMBER(F3),VLOOKUP($A3,List!$A$1:$B$29,2,FALSE))) | S3: =IF(IF(ISNUMBER(G3),VLOOKUP($A3,List!$A$1:$B$29,2,FALSE))=FALSE,"",IF(ISNUMBER(G3),VLOOKUP($A3,List!$A$1:$B$29,2,FALSE))) | T3: =IF(IF(ISNUMBER(H3),VLOOKUP($A3,List!$A$1:$B$29,2,FALSE))=FALSE,"",IF(ISNUMBER(H3),VLOOKUP($A3,List!$A$1:$B$29,2,FALSE))) | U3: =IF(IF(ISNUMBER(I3),VLOOKUP($A3,List!$A$1:$B$29,2,FALSE))=FALSE,"",IF(ISNUMBER(I3),VLOOKUP($A3,List!$A$1:$B$29,2,FALSE))) | ... Y3: =IF(IF(ISNUMBER(M3),VLOOKUP($A3,List!$A$1:$B$29,2,FALSE))=FALSE,"",IF(ISNUMBER(M3),VLOOKUP($A3,List!$A$1:$B$29,2,FALSE)))
A4: 28 | B4: 0.75 | C4: NA | D4: NA | E4: NA | F4: NA | G4: NA | H4: NA | I4: NA | J4: NA | K4: NA | L4: NA | M4: NA | N4: =IF(IF(ISNUMBER(B4),VLOOKUP($A4,List!$A$1:$B$29,2,FALSE))=FALSE,"",IF(ISNUMBER(B4),VLOOKUP($A4,List!$A$1:$B$29,2,FALSE))) -> Boating is my true passion in life | O4: =IF(IF(ISNUMBER(C4),VLOOKUP($A4,List!$A$1:$B$29,2,FALSE))=FALSE,"",IF(ISNUMBER(C4),VLOOKUP($A4,List!$A$1:$B$29,2,FALSE))) | P4: =IF(IF(ISNUMBER(D4),VLOOKUP($A4,List!$A$1:$B$29,2,FALSE))=FALSE,"",IF(ISNUMBER(D4),VLOOKUP($A4,List!$A$1:$B$29,2,FALSE))) | Q4: =IF(IF(ISNUMBER(E4),VLOOKUP($A4,List!$A$1:$B$29,2,FALSE))=FALSE,"",IF(ISNUMBER(E4),VLOOKUP($A4,List!$A$1:$B$29,2,FALSE))) | R4: =IF(IF(ISNUMBER(F4),VLOOKUP($A4,List!$A$1:$B$29,2,FALSE))=FALSE,"",IF(ISNUMBER(F4),VLOOKUP($A4,List!$A$1:$B$29,2,FALSE))) | S4: =IF(IF(ISNUMBER(G4),VLOOKUP($A4,List!$A$1:$B$29,2,FALSE))=FALSE,"",IF(ISNUMBER(G4),VLOOKUP($A4,List!$A$1:$B$29,2,FALSE))) | T4: =IF(IF(ISNUMBER(H4),VLOOKUP($A4,List!$A$1:$B$29,2,FALSE))=FALSE,"",IF(ISNUMBER(H4),VLOOKUP($A4,List!$A$1:$B$29,2,FALSE))) | U4: =IF(IF(ISNUMBER(I4),VLOOKUP($A4,List!$A$1:$B$29,2,FALSE))=FALSE,"",IF(ISNUMBER(I4),VLOOKUP($A4,List!$A$1:$B$29,2,FALSE))) | ... Y4: =IF(IF(ISNUMBER(M4),VLOOKUP($A4,List!$A$1:$B$29,2,FALSE))=FALSE,"",IF(ISNUMBER(M4),VLOOKUP($A4,List!$A$1:$B$29,2,FALSE)))
A5: 20 | B5: 0.64 | C5: NA | D5: NA | E5: NA | F5: NA | G5: NA | H5: NA | I5: NA | J5: NA | K5: NA | L5: NA | M5: NA | N5: =IF(IF(ISNUMBER(B5),VLOOKUP($A5,List!$A$1:$B$29,2,FALSE))=FALSE,"",IF(ISNUMBER(B5),VLOOKUP($A5,List!$A$1:$B$29,2,FALSE))) -> When not on my boat, I often find myself doing boating related activities | O5: =IF(IF(ISNUMBER(C5),VLOOKUP($A5,List!$A$1:$B$29,2,FALSE))=FALSE,"",IF(ISNUMBER(C5),VLOOKUP($A5,List!$A$1:$B$29,2,FALSE))) | P5: =IF(IF(ISNUMBER(D5),VLOOKUP($A5,List!$A$1:$B$29,2,FALSE))=FALSE,"",IF(ISNUMBER(D5),VLOOKUP($A5,List!$A$1:$B$29,2,FALSE))) | Q5: =IF(IF(ISNUMBER(E5),VLOOKUP($A5,List!$A$1:$B$29,2,FALSE))=FALSE,"",IF(ISNUMBER(E5),VLOOKUP($A5,List!$A$1:$B$29,2,FALSE))) | R5: =IF(IF(ISNUMBER(F5),VLOOKUP($A5,List!$A$1:$B$29,2,FALSE))=FALSE,"",IF(ISNUMBER(F5),VLOOKUP($A5,List!$A$1:$B$29,2,FALSE))) | S5: =IF(IF(ISNUMBER(G5),VLOOKUP($A5,List!$A$1:$B$29,2,FALSE))=FALSE,"",IF(ISNUMBER(G5),VLOOKUP($A5,List!$A$1:$B$29,2,FALSE))) | T5: =IF(IF(ISNUMBER(H5),VLOOKUP($A5,List!$A$1:$B$29,2,FALSE))=FALSE,"",IF(ISNUMBER(H5),VLOOKUP($A5,List!$A$1:$B$29,2,FALSE))) | U5: =IF(IF(ISNUMBER(I5),VLOOKUP($A5,List!$A$1:$B$29,2,FALSE))=FALSE,"",IF(ISNUMBER(I5),VLOOKUP($A5,List!$A$1:$B$29,2,FALSE))) | ... Y5: =IF(IF(ISNUMBER(M5),VLOOKUP($A5,List!$A$1:$B$29,2,FALSE))=FALSE,"",IF(ISNUMBER(M5),VLOOKUP($A5,List!$A$1:$B$29,2,FALSE)))
A6: 16 | B6: 0.63 | C6: NA | D6: NA | E6: NA | F6: NA | G6: NA | H6: NA | I6: NA | J6: NA | K6: NA | L6: NA | M6: NA | N6: =IF(IF(ISNUMBER(B6),VLOOKUP($A6,List!$A$1:$B$29,2,FALSE))=FALSE,"",IF(ISNUMBER(B6),VLOOKUP($A6,List!$A$1:$B$29,2,FALSE))) -> People tend to come to me for advice about boating | O6: =IF(IF(ISNUMBER(C6),VLOOKUP($A6,List!$A$1:$B$29,2,FALSE))=FALSE,"",IF(ISNUMBER(C6),VLOOKUP($A6,List!$A$1:$B$29,2,FALSE))) | P6: =IF(IF(ISNUMBER(D6),VLOOKUP($A6,List!$A$1:$B$29,2,FALSE))=FALSE,"",IF(ISNUMBER(D6),VLOOKUP($A6,List!$A$1:$B$29,2,FALSE))) | Q6: =IF(IF(ISNUMBER(E6),VLOOKUP($A6,List!$A$1:$B$29,2,FALSE))=FALSE,"",IF(ISNUMBER(E6),VLOOKUP($A6,List!$A$1:$B$29,2,FALSE))) | R6: =IF(IF(ISNUMBER(F6),VLOOKUP($A6,List!$A$1:$B$29,2,FALSE))=FALSE,"",IF(ISNUMBER(F6),VLOOKUP($A6,List!$A$1:$B$29,2,FALSE))) | S6: =IF(IF(ISNUMBER(G6),VLOOKUP($A6,List!$A$1:$B$29,2,FALSE))=FALSE,"",IF(ISNUMBER(G6),VLOOKUP($A6,List!$A$1:$B$29,2,FALSE))) | T6: =IF(IF(ISNUMBER(H6),VLOOKUP($A6,List!$A$1:$B$29,2,FALSE))=FALSE,"",IF(ISNUMBER(H6),VLOOKUP($A6,List!$A$1:$B$29,2,FALSE))) | U6: =IF(IF(ISNUMBER(I6),VLOOKUP($A6,List!$A$1:$B$29,2,FALSE))=FALSE,"",IF(ISNUMBER(I6),VLOOKUP($A6,List!$A$1:$B$29,2,FALSE))) | ... Y6: =IF(IF(ISNUMBER(M6),VLOOKUP($A6,List!$A$1:$B$29,2,FALSE))=FALSE,"",IF(ISNUMBER(M6),VLOOKUP($A6,List!$A$1:$B$29,2,FALSE)))
A7: 23 | B7: 0.58 | C7: NA | D7: NA | E7: NA | F7: NA | G7: NA | H7: NA | I7: NA | J7: NA | K7: NA | L7: NA | M7: NA | N7: =IF(IF(ISNUMBER(B7),VLOOKUP($A7,List!$A$1:$B$29,2,FALSE))=FALSE,"",IF(ISNUMBER(B7),VLOOKUP($A7,List!$A$1:$B$29,2,FALSE))) -> Boating allows me to excel in the sports that I am passionate about | O7: =IF(IF(ISNUMBER(C7),VLOOKUP($A7,List!$A$1:$B$29,2,FALSE))=FALSE,"",IF(ISNUMBER(C7),VLOOKUP($A7,List!$A$1:$B$29,2,FALSE))) | P7: =IF(IF(ISNUMBER(D7),VLOOKUP($A7,List!$A$1:$B$29,2,FALSE))=FALSE,"",IF(ISNUMBER(D7),VLOOKUP($A7,List!$A$1:$B$29,2,FALSE))) | Q7: =IF(IF(ISNUMBER(E7),VLOOKUP($A7,List!$A$1:$B$29,2,FALSE))=FALSE,"",IF(ISNUMBER(E7),VLOOKUP($A7,List!$A$1:$B$29,2,FALSE))) | R7: =IF(IF(ISNUMBER(F7),VLOOKUP($A7,List!$A$1:$B$29,2,FALSE))=FALSE,"",IF(ISNUMBER(F7),VLOOKUP($A7,List!$A$1:$B$29,2,FALSE))) | S7: =IF(IF(ISNUMBER(G7),VLOOKUP($A7,List!$A$1:$B$29,2,FALSE))=FALSE,"",IF(ISNUMBER(G7),VLOOKUP($A7,List!$A$1:$B$29,2,FALSE))) | T7: =IF(IF(ISNUMBER(H7),VLOOKUP($A7,List!$A$1:$B$29,2,FALSE))=FALSE,"",IF(ISNUMBER(H7),VLOOKUP($A7,List!$A$1:$B$29,2,FALSE))) | U7: =IF(IF(ISNUMBER(I7),VLOOKUP($A7,List!$A$1:$B$29,2,FALSE))=FALSE,"",IF(ISNUMBER(I7),VLOOKUP($A7,List!$A$1:$B$29,2,FALSE))) | ... Y7: =IF(IF(ISNUMBER(M7),VLOOKUP($A7,List!$A$1:$B$29,2,FALSE))=FALSE,"",IF(ISNUMBER(M7),VLOOKUP($A7,List!$A$1:$B$29,2,FALSE)))
A8: 17 | B8: 0.56 | C8: NA | D8: NA | E8: NA | F8: NA | G8: NA | H8: NA | I8: NA | J8: NA | K8: NA | L8: NA | M8: NA | N8: =IF(IF(ISNUMBER(B8),VLOOKUP($A8,List!$A$1:$B$29,2,FALSE))=FALSE,"",IF(ISNUMBER(B8),VLOOKUP($A8,List!$A$1:$B$29,2,FALSE))) -> I consider myself more knowledgeable about boating than the rest of my boating peers | O8: =IF(IF(ISNUMBER(C8),VLOOKUP($A8,List!$A$1:$B$29,2,FALSE))=FALSE,"",IF(ISNUMBER(C8),VLOOKUP($A8,List!$A$1:$B$29,2,FALSE))) | P8: =IF(IF(ISNUMBER(D8),VLOOKUP($A8,List!$A$1:$B$29,2,FALSE))=FALSE,"",IF(ISNUMBER(D8),VLOOKUP($A8,List!$A$1:$B$29,2,FALSE))) | Q8: =IF(IF(ISNUMBER(E8),VLOOKUP($A8,List!$A$1:$B$29,2,FALSE))=FALSE,"",IF(ISNUMBER(E8),VLOOKUP($A8,List!$A$1:$B$29,2,FALSE))) | R8: =IF(IF(ISNUMBER(F8),VLOOKUP($A8,List!$A$1:$B$29,2,FALSE))=FALSE,"",IF(ISNUMBER(F8),VLOOKUP($A8,List!$A$1:$B$29,2,FALSE))) | S8: =IF(IF(ISNUMBER(G8),VLOOKUP($A8,List!$A$1:$B$29,2,FALSE))=FALSE,"",IF(ISNUMBER(G8),VLOOKUP($A8,List!$A$1:$B$29,2,FALSE))) | T8: =IF(IF(ISNUMBER(H8),VLOOKUP($A8,List!$A$1:$B$29,2,FALSE))=FALSE,"",IF(ISNUMBER(H8),VLOOKUP($A8,List!$A$1:$B$29,2,FALSE))) | U8: =IF(IF(ISNUMBER(I8),VLOOKUP($A8,List!$A$1:$B$29,2,FALSE))=FALSE,"",IF(ISNUMBER(I8),VLOOKUP($A8,List!$A$1:$B$29,2,FALSE))) | ... Y8: =IF(IF(ISNUMBER(M8),VLOOKUP($A8,List!$A$1:$B$29,2,FALSE))=FALSE,"",IF(ISNUMBER(M8),VLOOKUP($A8,List!$A$1:$B$29,2,FALSE)))
A9: 26 | B9: NA | C9: NA | D9: NA | E9: NA | F9: NA | G9: NA | H9: NA | I9: NA | J9: NA | K9: NA | L9: NA | M9: NA | N9: =IF(IF(ISNUMBER(B9),VLOOKUP($A9,List!$A$1:$B$29,2,FALSE))=FALSE,"",IF(ISNUMBER(B9),VLOOKUP($A9,List!$A$1:$B$29,2,FALSE))) | O9: =IF(IF(ISNUMBER(C9),VLOOKUP($A9,List!$A$1:$B$29,2,FALSE))=FALSE,"",IF(ISNUMBER(C9),VLOOKUP($A9,List!$A$1:$B$29,2,FALSE))) | P9: =IF(IF(ISNUMBER(D9),VLOOKUP($A9,List!$A$1:$B$29,2,FALSE))=FALSE,"",IF(ISNUMBER(D9),VLOOKUP($A9,List!$A$1:$B$29,2,FALSE))) | Q9: =IF(IF(ISNUMBER(E9),VLOOKUP($A9,List!$A$1:$B$29,2,FALSE))=FALSE,"",IF(ISNUMBER(E9),VLOOKUP($A9,List!$A$1:$B$29,2,FALSE))) | R9: =IF(IF(ISNUMBER(F9),VLOOKUP($A9,List!$A$1:$B$29,2,FALSE))=FALSE,"",IF(ISNUMBER(F9),VLOOKUP($A9,List!$A$1:$B$29,2,FALSE))) | S9: =IF(IF(ISNUMBER(G9),VLOOKUP($A9,List!$A$1:$B$29,2,FALSE))=FALSE,"",IF(ISNUMBER(G9),VLOOKUP($A9,List!$A$1:$B$29,2,FALSE))) | T9: =IF(IF(ISNUMBER(H9),VLOOKUP($A9,List!$A$1:$B$29,2,FALSE))=FALSE,"",IF(ISNUMBER(H9),VLOOKUP($A9,List!$A$1:$B$29,2,FALSE))) | U9: =IF(IF(ISNUMBER(I9),VLOOKUP($A9,List!$A$1:$B$29,2,FALSE))=FALSE,"",IF(ISNUMBER(I9),VLOOKUP($A9,List!$A$1:$B$29,2,FALSE))) | ... Y9: =IF(IF(ISNUMBER(M9),VLOOKUP($A9,List!$A$1:$B$29,2,FALSE))=FALSE,"",IF(ISNUMBER(M9),VLOOKUP($A9,List!$A$1:$B$29,2,FALSE)))
A10: 22 | B10: NA | C10: NA | D10: NA | E10: NA | F10: NA | G10: NA | H10: NA | I10: NA | J10: NA | K10: NA | L10: NA | M10: NA | N10: =IF(IF(ISNUMBER(B10),VLOOKUP($A10,List!$A$1:$B$29,2,FALSE))=FALSE,"",IF(ISNUMBER(B10),VLOOKUP($A10,List!$A$1:$B$29,2,FALSE))) | O10: =IF(IF(ISNUMBER(C10),VLOOKUP($A10,List!$A$1:$B$29,2,FALSE))=FALSE,"",IF(ISNUMBER(C10),VLOOKUP($A10,List!$A$1:$B$29,2,FALSE))) | P10: =IF(IF(ISNUMBER(D10),VLOOKUP($A10,List!$A$1:$B$29,2,FALSE))=FALSE,"",IF(ISNUMBER(D10),VLOOKUP($A10,List!$A$1:$B$29,2,FALSE))) | Q10: =IF(IF(ISNUMBER(E10),VLOOKUP($A10,List!$A$1:$B$29,2,FALSE))=FALSE,"",IF(ISNUMBER(E10),VLOOKUP($A10,List!$A$1:$B$29,2,FALSE))) | R10: =IF(IF(ISNUMBER(F10),VLOOKUP($A10,List!$A$1:$B$29,2,FALSE))=FALSE,"",IF(ISNUMBER(F10),VLOOKUP($A10,List!$A$1:$B$29,2,FALSE))) | S10: =IF(IF(ISNUMBER(G10),VLOOKUP($A10,List!$A$1:$B$29,2,FALSE))=FALSE,"",IF(ISNUMBER(G10),VLOOKUP($A10,List!$A$1:$B$29,2,FALSE))) | T10: =IF(IF(ISNUMBER(H10),VLOOKUP($A10,List!$A$1:$B$29,2,FALSE))=FALSE,"",IF(ISNUMBER(H10),VLOOKUP($A10,List!$A$1:$B$29,2,FALSE))) | U10: =IF(IF(ISNUMBER(I10),VLOOKUP($A10,List!$A$1:$B$29,2,FALSE))=FALSE,"",IF(ISNUMBER(I10),VLOOKUP($A10,List!$A$1:$B$29,2,FALSE))) | ... Y10: =IF(IF(ISNUMBER(M10),VLOOKUP($A10,List!$A$1:$B$29,2,FALSE))=FALSE,"",IF(ISNUMBER(M10),VLOOKUP($A10,List!$A$1:$B$29,2,FALSE)))
A11: 3 | B11: NA | C11: NA | D11: NA | E11: 0.55 | F11: NA | G11: NA | H11: NA | I11: NA | J11: NA | K11: NA | L11: NA | M11: NA | N11: =IF(IF(ISNUMBER(B11),VLOOKUP($A11,List!$A$1:$B$29,2,FALSE))=FALSE,"",IF(ISNUMBER(B11),VLOOKUP($A11,List!$A$1:$B$29,2,FALSE))) | O11: =IF(IF(ISNUMBER(C11),VLOOKUP($A11,List!$A$1:$B$29,2,FALSE))=FALSE,"",IF(ISNUMBER(C11),VLOOKUP($A11,List!$A$1:$B$29,2,FALSE))) | P11: =IF(IF(ISNUMBER(D11),VLOOKUP($A11,List!$A$1:$B$29,2,FALSE))=FALSE,"",IF(ISNUMBER(D11),VLOOKUP($A11,List!$A$1:$B$29,2,FALSE))) | Q11: =IF(IF(ISNUMBER(E11),VLOOKUP($A11,List!$A$1:$B$29,2,FALSE))=FALSE,"",IF(ISNUMBER(E11),VLOOKUP($A11,List!$A$1:$B$29,2,FALSE))) -> The brand of the boat I buy says a lot about who I am | R11: =IF(IF(ISNUMBER(F11),VLOOKUP($A11,List!$A$1:$B$29,2,FALSE))=FALSE,"",IF(ISNUMBER(F11),VLOOKUP($A11,List!$A$1:$B$29,2,FALSE))) | S11: =IF(IF(ISNUMBER(G11),VLOOKUP($A11,List!$A$1:$B$29,2,FALSE))=FALSE,"",IF(ISNUMBER(G11),VLOOKUP($A11,List!$A$1:$B$29,2,FALSE))) | T11: =IF(IF(ISNUMBER(H11),VLOOKUP($A11,List!$A$1:$B$29,2,FALSE))=FALSE,"",IF(ISNUMBER(H11),VLOOKUP($A11,List!$A$1:$B$29,2,FALSE))) | U11: =IF(IF(ISNUMBER(I11),VLOOKUP($A11,List!$A$1:$B$29,2,FALSE))=FALSE,"",IF(ISNUMBER(I11),VLOOKUP($A11,List!$A$1:$B$29,2,FALSE))) | ... Y11: =IF(IF(ISNUMBER(M11),VLOOKUP($A11,List!$A$1:$B$29,2,FALSE))=FALSE,"",IF(ISNUMBER(M11),VLOOKUP($A11,List!$A$1:$B$29,2,FALSE)))
A12: 9 | B12: NA | C12: NA | D12: NA | E12: 0.64 | F12: NA | G12: NA | H12: NA | I12: NA | J12: NA | K12: NA | L12: NA | M12: NA | N12: =IF(IF(ISNUMBER(B12),VLOOKUP($A12,List!$A$1:$B$29,2,FALSE))=FALSE,"",IF(ISNUMBER(B12),VLOOKUP($A12,List!$A$1:$B$29,2,FALSE))) | O12: =IF(IF(ISNUMBER(C12),VLOOKUP($A12,List!$A$1:$B$29,2,FALSE))=FALSE,"",IF(ISNUMBER(C12),VLOOKUP($A12,List!$A$1:$B$29,2,FALSE))) | P12: =IF(IF(ISNUMBER(D12),VLOOKUP($A12,List!$A$1:$B$29,2,FALSE))=FALSE,"",IF(ISNUMBER(D12),VLOOKUP($A12,List!$A$1:$B$29,2,FALSE))) | Q12: =IF(IF(ISNUMBER(E12),VLOOKUP($A12,List!$A$1:$B$29,2,FALSE))=FALSE,"",IF(ISNUMBER(E12),VLOOKUP($A12,List!$A$1:$B$29,2,FALSE))) -> I see my boat as status symbol | R12: =IF(IF(ISNUMBER(F12),VLOOKUP($A12,List!$A$1:$B$29,2,FALSE))=FALSE,"",IF(ISNUMBER(F12),VLOOKUP($A12,List!$A$1:$B$29,2,FALSE))) | S12: =IF(IF(ISNUMBER(G12),VLOOKUP($A12,List!$A$1:$B$29,2,FALSE))=FALSE,"",IF(ISNUMBER(G12),VLOOKUP($A12,List!$A$1:$B$29,2,FALSE))) | T12: =IF(IF(ISNUMBER(H12),VLOOKUP($A12,List!$A$1:$B$29,2,FALSE))=FALSE,"",IF(ISNUMBER(H12),VLOOKUP($A12,List!$A$1:$B$29,2,FALSE))) | U12: =IF(IF(ISNUMBER(I12),VLOOKUP($A12,List!$A$1:$B$29,2,FALSE))=FALSE,"",IF(ISNUMBER(I12),VLOOKUP($A12,List!$A$1:$B$29,2,FALSE))) | ... Y12: =IF(IF(ISNUMBER(M12),VLOOKUP($A12,List!$A$1:$B$29,2,FALSE))=FALSE,"",IF(ISNUMBER(M12),VLOOKUP($A12,List!$A$1:$B$29,2,FALSE)))
A13: 13 | B13: NA | C13: 0.75 | D13: NA | E13: NA | F13: NA | G13: NA | H13: NA | I13: NA | J13: NA | K13: NA | L13: NA | M13: NA | N13: =IF(IF(ISNUMBER(B13),VLOOKUP($A13,List!$A$1:$B$29,2,FALSE))=FALSE,"",IF(ISNUMBER(B13),VLOOKUP($A13,List!$A$1:$B$29,2,FALSE))) | O13: =IF(IF(ISNUMBER(C13),VLOOKUP($A13,List!$A$1:$B$29,2,FALSE))=FALSE,"",IF(ISNUMBER(C13),VLOOKUP($A13,List!$A$1:$B$29,2,FALSE))) -> When buying a boat, I tend to buy the latest and greatest | P13: =IF(IF(ISNUMBER(D13),VLOOKUP($A13,List!$A$1:$B$29,2,FALSE))=FALSE,"",IF(ISNUMBER(D13),VLOOKUP($A13,List!$A$1:$B$29,2,FALSE))) | Q13: =IF(IF(ISNUMBER(E13),VLOOKUP($A13,List!$A$1:$B$29,2,FALSE))=FALSE,"",IF(ISNUMBER(E13),VLOOKUP($A13,List!$A$1:$B$29,2,FALSE))) | R13: =IF(IF(ISNUMBER(F13),VLOOKUP($A13,List!$A$1:$B$29,2,FALSE))=FALSE,"",IF(ISNUMBER(F13),VLOOKUP($A13,List!$A$1:$B$29,2,FALSE))) | S13: =IF(IF(ISNUMBER(G13),VLOOKUP($A13,List!$A$1:$B$29,2,FALSE))=FALSE,"",IF(ISNUMBER(G13),VLOOKUP($A13,List!$A$1:$B$29,2,FALSE))) | T13: =IF(IF(ISNUMBER(H13),VLOOKUP($A13,List!$A$1:$B$29,2,FALSE))=FALSE,"",IF(ISNUMBER(H13),VLOOKUP($A13,List!$A$1:$B$29,2,FALSE))) | U13: =IF(IF(ISNUMBER(I13),VLOOKUP($A13,List!$A$1:$B$29,2,FALSE))=FALSE,"",IF(ISNUMBER(I13),VLOOKUP($A13,List!$A$1:$B$29,2,FALSE))) | ... Y13: =IF(IF(ISNUMBER(M13),VLOOKUP($A13,List!$A$1:$B$29,2,FALSE))=FALSE,"",IF(ISNUMBER(M13),VLOOKUP($A13,List!$A$1:$B$29,2,FALSE)))
A14: 14 | B14: NA | C14: 0.75 | D14: NA | E14: NA | F14: NA | G14: NA | H14: NA | I14: NA | J14: NA | K14: NA | L14: NA | M14: NA | N14: =IF(IF(ISNUMBER(B14),VLOOKUP($A14,List!$A$1:$B$29,2,FALSE))=FALSE,"",IF(ISNUMBER(B14),VLOOKUP($A14,List!$A$1:$B$29,2,FALSE))) | O14: =IF(IF(ISNUMBER(C14),VLOOKUP($A14,List!$A$1:$B$29,2,FALSE))=FALSE,"",IF(ISNUMBER(C14),VLOOKUP($A14,List!$A$1:$B$29,2,FALSE))) -> When buying accessories for my boat, I tend to buy the latest and greatest | P14: =IF(IF(ISNUMBER(D14),VLOOKUP($A14,List!$A$1:$B$29,2,FALSE))=FALSE,"",IF(ISNUMBER(D14),VLOOKUP($A14,List!$A$1:$B$29,2,FALSE))) | Q14: =IF(IF(ISNUMBER(E14),VLOOKUP($A14,List!$A$1:$B$29,2,FALSE))=FALSE,"",IF(ISNUMBER(E14),VLOOKUP($A14,List!$A$1:$B$29,2,FALSE))) | R14: =IF(IF(ISNUMBER(F14),VLOOKUP($A14,List!$A$1:$B$29,2,FALSE))=FALSE,"",IF(ISNUMBER(F14),VLOOKUP($A14,List!$A$1:$B$29,2,FALSE))) | S14: =IF(IF(ISNUMBER(G14),VLOOKUP($A14,List!$A$1:$B$29,2,FALSE))=FALSE,"",IF(ISNUMBER(G14),VLOOKUP($A14,List!$A$1:$B$29,2,FALSE))) | T14: =IF(IF(ISNUMBER(H14),VLOOKUP($A14,List!$A$1:$B$29,2,FALSE))=FALSE,"",IF(ISNUMBER(H14),VLOOKUP($A14,List!$A$1:$B$29,2,FALSE))) | U14: =IF(IF(ISNUMBER(I14),VLOOKUP($A14,List!$A$1:$B$29,2,FALSE))=FALSE,"",IF(ISNUMBER(I14),VLOOKUP($A14,List!$A$1:$B$29,2,FALSE))) | ... Y14: =IF(IF(ISNUMBER(M14),VLOOKUP($A14,List!$A$1:$B$29,2,FALSE))=FALSE,"",IF(ISNUMBER(M14),VLOOKUP($A14,List!$A$1:$B$29,2,FALSE)))
A15: 5 | B15: NA | C15: NA | D15: NA | E15: NA | F15: NA | G15: NA | H15: NA | I15: NA | J15: NA | K15: NA | L15: NA | M15: NA | N15: =IF(IF(ISNUMBER(B15),VLOOKUP($A15,List!$A$1:$B$29,2,FALSE))=FALSE,"",IF(ISNUMBER(B15),VLOOKUP($A15,List!$A$1:$B$29,2,FALSE))) | O15: =IF(IF(ISNUMBER(C15),VLOOKUP($A15,List!$A$1:$B$29,2,FALSE))=FALSE,"",IF(ISNUMBER(C15),VLOOKUP($A15,List!$A$1:$B$29,2,FALSE))) | P15: =IF(IF(ISNUMBER(D15),VLOOKUP($A15,List!$A$1:$B$29,2,FALSE))=FALSE,"",IF(ISNUMBER(D15),VLOOKUP($A15,List!$A$1:$B$29,2,FALSE))) | Q15: =IF(IF(ISNUMBER(E15),VLOOKUP($A15,List!$A$1:$B$29,2,FALSE))=FALSE,"",IF(ISNUMBER(E15),VLOOKUP($A15,List!$A$1:$B$29,2,FALSE))) | R15: =IF(IF(ISNUMBER(F15),VLOOKUP($A15,List!$A$1:$B$29,2,FALSE))=FALSE,"",IF(ISNUMBER(F15),VLOOKUP($A15,List!$A$1:$B$29,2,FALSE))) | S15: =IF(IF(ISNUMBER(G15),VLOOKUP($A15,List!$A$1:$B$29,2,FALSE))=FALSE,"",IF(ISNUMBER(G15),VLOOKUP($A15,List!$A$1:$B$29,2,FALSE))) | T15: =IF(IF(ISNUMBER(H15),VLOOKUP($A15,List!$A$1:$B$29,2,FALSE))=FALSE,"",IF(ISNUMBER(H15),VLOOKUP($A15,List!$A$1:$B$29,2,FALSE))) | U15: =IF(IF(ISNUMBER(I15),VLOOKUP($A15,List!$A$1:$B$29,2,FALSE))=FALSE,"",IF(ISNUMBER(I15),VLOOKUP($A15,List!$A$1:$B$29,2,FALSE))) | ... Y15: =IF(IF(ISNUMBER(M15),VLOOKUP($A15,List!$A$1:$B$29,2,FALSE))=FALSE,"",IF(ISNUMBER(M15),VLOOKUP($A15,List!$A$1:$B$29,2,FALSE)))
A16: 25 | B16: NA | C16: NA | D16: NA | E16: NA | F16: NA | G16: NA | H16: NA | I16: NA | J16: NA | K16: NA | L16: NA | M16: NA | N16: =IF(IF(ISNUMBER(B16),VLOOKUP($A16,List!$A$1:$B$29,2,FALSE))=FALSE,"",IF(ISNUMBER(B16),VLOOKUP($A16,List!$A$1:$B$29,2,FALSE))) | O16: =IF(IF(ISNUMBER(C16),VLOOKUP($A16,List!$A$1:$B$29,2,FALSE))=FALSE,"",IF(ISNUMBER(C16),VLOOKUP($A16,List!$A$1:$B$29,2,FALSE))) | P16: =IF(IF(ISNUMBER(D16),VLOOKUP($A16,List!$A$1:$B$29,2,FALSE))=FALSE,"",IF(ISNUMBER(D16),VLOOKUP($A16,List!$A$1:$B$29,2,FALSE))) | Q16: =IF(IF(ISNUMBER(E16),VLOOKUP($A16,List!$A$1:$B$29,2,FALSE))=FALSE,"",IF(ISNUMBER(E16),VLOOKUP($A16,List!$A$1:$B$29,2,FALSE))) | R16: =IF(IF(ISNUMBER(F16),VLOOKUP($A16,List!$A$1:$B$29,2,FALSE))=FALSE,"",IF(ISNUMBER(F16),VLOOKUP($A16,List!$A$1:$B$29,2,FALSE))) | S16: =IF(IF(ISNUMBER(G16),VLOOKUP($A16,List!$A$1:$B$29,2,FALSE))=FALSE,"",IF(ISNUMBER(G16),VLOOKUP($A16,List!$A$1:$B$29,2,FALSE))) | T16: =IF(IF(ISNUMBER(H16),VLOOKUP($A16,List!$A$1:$B$29,2,FALSE))=FALSE,"",IF(ISNUMBER(H16),VLOOKUP($A16,List!$A$1:$B$29,2,FALSE))) | U16: =IF(IF(ISNUMBER(I16),VLOOKUP($A16,List!$A$1:$B$29,2,FALSE))=FALSE,"",IF(ISNUMBER(I16),VLOOKUP($A16,List!$A$1:$B$29,2,FALSE))) | ... Y16: =IF(IF(ISNUMBER(M16),VLOOKUP($A16,List!$A$1:$B$29,2,FALSE))=FALSE,"",IF(ISNUMBER(M16),VLOOKUP($A16,List!$A$1:$B$29,2,FALSE)))
A17: 15 | B17: NA | C17: 0.63 | D17: NA | E17: NA | F17: NA | G17: NA | H17: NA | I17: NA | J17: NA | K17: NA | L17: NA | M17: NA | N17: =IF(IF(ISNUMBER(B17),VLOOKUP($A17,List!$A$1:$B$29,2,FALSE))=FALSE,"",IF(ISNUMBER(B17),VLOOKUP($A17,List!$A$1:$B$29,2,FALSE))) | O17: =IF(IF(ISNUMBER(C17),VLOOKUP($A17,List!$A$1:$B$29,2,FALSE))=FALSE,"",IF(ISNUMBER(C17),VLOOKUP($A17,List!$A$1:$B$29,2,FALSE))) -> I am serious about the technology on my boat | P17: =IF(IF(ISNUMBER(D17),VLOOKUP($A17,List!$A$1:$B$29,2,FALSE))=FALSE,"",IF(ISNUMBER(D17),VLOOKUP($A17,List!$A$1:$B$29,2,FALSE))) | Q17: =IF(IF(ISNUMBER(E17),VLOOKUP($A17,List!$A$1:$B$29,2,FALSE))=FALSE,"",IF(ISNUMBER(E17),VLOOKUP($A17,List!$A$1:$B$29,2,FALSE))) | R17: =IF(IF(ISNUMBER(F17),VLOOKUP($A17,List!$A$1:$B$29,2,FALSE))=FALSE,"",IF(ISNUMBER(F17),VLOOKUP($A17,List!$A$1:$B$29,2,FALSE))) | S17: =IF(IF(ISNUMBER(G17),VLOOKUP($A17,List!$A$1:$B$29,2,FALSE))=FALSE,"",IF(ISNUMBER(G17),VLOOKUP($A17,List!$A$1:$B$29,2,FALSE))) | T17: =IF(IF(ISNUMBER(H17),VLOOKUP($A17,List!$A$1:$B$29,2,FALSE))=FALSE,"",IF(ISNUMBER(H17),VLOOKUP($A17,List!$A$1:$B$29,2,FALSE))) | U17: =IF(IF(ISNUMBER(I17),VLOOKUP($A17,List!$A$1:$B$29,2,FALSE))=FALSE,"",IF(ISNUMBER(I17),VLOOKUP($A17,List!$A$1:$B$29,2,FALSE))) | ... Y17: =IF(IF(ISNUMBER(M17),VLOOKUP($A17,List!$A$1:$B$29,2,FALSE))=FALSE,"",IF(ISNUMBER(M17),VLOOKUP($A17,List!$A$1:$B$29,2,FALSE)))
A18: 6 | B18: NA | C18: NA | D18: NA | E18: 0.62 | F18: NA | G18: NA | H18: NA | I18: NA | J18: NA | K18: NA | L18: NA | M18: NA | N18: =IF(IF(ISNUMBER(B18),VLOOKUP($A18,List!$A$1:$B$29,2,FALSE))=FALSE,"",IF(ISNUMBER(B18),VLOOKUP($A18,List!$A$1:$B$29,2,FALSE))) | O18: =IF(IF(ISNUMBER(C18),VLOOKUP($A18,List!$A$1:$B$29,2,FALSE))=FALSE,"",IF(ISNUMBER(C18),VLOOKUP($A18,List!$A$1:$B$29,2,FALSE))) | P18: =IF(IF(ISNUMBER(D18),VLOOKUP($A18,List!$A$1:$B$29,2,FALSE))=FALSE,"",IF(ISNUMBER(D18),VLOOKUP($A18,List!$A$1:$B$29,2,FALSE))) | Q18: =IF(IF(ISNUMBER(E18),VLOOKUP($A18,List!$A$1:$B$29,2,FALSE))=FALSE,"",IF(ISNUMBER(E18),VLOOKUP($A18,List!$A$1:$B$29,2,FALSE))) -> Owning a boat is a way of rewarding myself for hard work | R18: =IF(IF(ISNUMBER(F18),VLOOKUP($A18,List!$A$1:$B$29,2,FALSE))=FALSE,"",IF(ISNUMBER(F18),VLOOKUP($A18,List!$A$1:$B$29,2,FALSE))) | S18: =IF(IF(ISNUMBER(G18),VLOOKUP($A18,List!$A$1:$B$29,2,FALSE))=FALSE,"",IF(ISNUMBER(G18),VLOOKUP($A18,List!$A$1:$B$29,2,FALSE))) | T18: =IF(IF(ISNUMBER(H18),VLOOKUP($A18,List!$A$1:$B$29,2,FALSE))=FALSE,"",IF(ISNUMBER(H18),VLOOKUP($A18,List!$A$1:$B$29,2,FALSE))) | U18: =IF(IF(ISNUMBER(I18),VLOOKUP($A18,List!$A$1:$B$29,2,FALSE))=FALSE,"",IF(ISNUMBER(I18),VLOOKUP($A18,List!$A$1:$B$29,2,FALSE))) | ... Y18: =IF(IF(ISNUMBER(M18),VLOOKUP($A18,List!$A$1:$B$29,2,FALSE))=FALSE,"",IF(ISNUMBER(M18),VLOOKUP($A18,List!$A$1:$B$29,2,FALSE)))
A19: 7 | B19: NA | C19: NA | D19: NA | E19: 0.74 | F19: NA | G19: NA | H19: NA | I19: NA | J19: NA | K19: NA | L19: NA | M19: NA | N19: =IF(IF(ISNUMBER(B19),VLOOKUP($A19,List!$A$1:$B$29,2,FALSE))=FALSE,"",IF(ISNUMBER(B19),VLOOKUP($A19,List!$A$1:$B$29,2,FALSE))) | O19: =IF(IF(ISNUMBER(C19),VLOOKUP($A19,List!$A$1:$B$29,2,FALSE))=FALSE,"",IF(ISNUMBER(C19),VLOOKUP($A19,List!$A$1:$B$29,2,FALSE))) | P19: =IF(IF(ISNUMBER(D19),VLOOKUP($A19,List!$A$1:$B$29,2,FALSE))=FALSE,"",IF(ISNUMBER(D19),VLOOKUP($A19,List!$A$1:$B$29,2,FALSE))) | Q19: =IF(IF(ISNUMBER(E19),VLOOKUP($A19,List!$A$1:$B$29,2,FALSE))=FALSE,"",IF(ISNUMBER(E19),VLOOKUP($A19,List!$A$1:$B$29,2,FALSE))) -> Owning a boat gives me a sense of achievement | R19: =IF(IF(ISNUMBER(F19),VLOOKUP($A19,List!$A$1:$B$29,2,FALSE))=FALSE,"",IF(ISNUMBER(F19),VLOOKUP($A19,List!$A$1:$B$29,2,FALSE))) | S19: =IF(IF(ISNUMBER(G19),VLOOKUP($A19,List!$A$1:$B$29,2,FALSE))=FALSE,"",IF(ISNUMBER(G19),VLOOKUP($A19,List!$A$1:$B$29,2,FALSE))) | T19: =IF(IF(ISNUMBER(H19),VLOOKUP($A19,List!$A$1:$B$29,2,FALSE))=FALSE,"",IF(ISNUMBER(H19),VLOOKUP($A19,List!$A$1:$B$29,2,FALSE))) | U19: =IF(IF(ISNUMBER(I19),VLOOKUP($A19,List!$A$1:$B$29,2,FALSE))=FALSE,"",IF(ISNUMBER(I19),VLOOKUP($A19,List!$A$1:$B$29,2,FALSE))) | ... Y19: =IF(IF(ISNUMBER(M19),VLOOKUP($A19,List!$A$1:$B$29,2,FALSE))=FALSE,"",IF(ISNUMBER(M19),VLOOKUP($A19,List!$A$1:$B$29,2,FALSE)))
A20: 12 | B20: NA | C20: NA | D20: NA | E20: NA | F20: 0.63 | G20: NA | H20: NA | I20: NA | J20: NA | K20: NA | L20: NA | M20: NA | N20: =IF(IF(ISNUMBER(B20),VLOOKUP($A20,List!$A$1:$B$29,2,FALSE))=FALSE,"",IF(ISNUMBER(B20),VLOOKUP($A20,List!$A$1:$B$29,2,FALSE))) | O20: =IF(IF(ISNUMBER(C20),VLOOKUP($A20,List!$A$1:$B$29,2,FALSE))=FALSE,"",IF(ISNUMBER(C20),VLOOKUP($A20,List!$A$1:$B$29,2,FALSE))) | P20: =IF(IF(ISNUMBER(D20),VLOOKUP($A20,List!$A$1:$B$29,2,FALSE))=FALSE,"",IF(ISNUMBER(D20),VLOOKUP($A20,List!$A$1:$B$29,2,FALSE))) | Q20: =IF(IF(ISNUMBER(E20),VLOOKUP($A20,List!$A$1:$B$29,2,FALSE))=FALSE,"",IF(ISNUMBER(E20),VLOOKUP($A20,List!$A$1:$B$29,2,FALSE))) | R20: =IF(IF(ISNUMBER(F20),VLOOKUP($A20,List!$A$1:$B$29,2,FALSE))=FALSE,"",IF(ISNUMBER(F20),VLOOKUP($A20,List!$A$1:$B$29,2,FALSE))) -> When it comes to boating, I tend to prefer a basic boat with little to no frills | S20: =IF(IF(ISNUMBER(G20),VLOOKUP($A20,List!$A$1:$B$29,2,FALSE))=FALSE,"",IF(ISNUMBER(G20),VLOOKUP($A20,List!$A$1:$B$29,2,FALSE))) | T20: =IF(IF(ISNUMBER(H20),VLOOKUP($A20,List!$A$1:$B$29,2,FALSE))=FALSE,"",IF(ISNUMBER(H20),VLOOKUP($A20,List!$A$1:$B$29,2,FALSE))) | U20: =IF(IF(ISNUMBER(I20),VLOOKUP($A20,List!$A$1:$B$29,2,FALSE))=FALSE,"",IF(ISNUMBER(I20),VLOOKUP($A20,List!$A$1:$B$29,2,FALSE))) | ... Y20: =IF(IF(ISNUMBER(M20),VLOOKUP($A20,List!$A$1:$B$29,2,FALSE))=FALSE,"",IF(ISNUMBER(M20),VLOOKUP($A20,List!$A$1:$B$29,2,FALSE)))
A21: 24 | B21: NA | C21: NA | D21: NA | E21: NA | F21: NA | G21: NA | H21: NA | I21: NA | J21: NA | K21: NA | L21: NA | M21: 0.77 | N21: =IF(IF(ISNUMBER(B21),VLOOKUP($A21,List!$A$1:$B$29,2,FALSE))=FALSE,"",IF(ISNUMBER(B21),VLOOKUP($A21,List!$A$1:$B$29,2,FALSE))) | O21: =IF(IF(ISNUMBER(C21),VLOOKUP($A21,List!$A$1:$B$29,2,FALSE))=FALSE,"",IF(ISNUMBER(C21),VLOOKUP($A21,List!$A$1:$B$29,2,FALSE))) | P21: =IF(IF(ISNUMBER(D21),VLOOKUP($A21,List!$A$1:$B$29,2,FALSE))=FALSE,"",IF(ISNUMBER(D21),VLOOKUP($A21,List!$A$1:$B$29,2,FALSE))) | Q21: =IF(IF(ISNUMBER(E21),VLOOKUP($A21,List!$A$1:$B$29,2,FALSE))=FALSE,"",IF(ISNUMBER(E21),VLOOKUP($A21,List!$A$1:$B$29,2,FALSE))) | R21: =IF(IF(ISNUMBER(F21),VLOOKUP($A21,List!$A$1:$B$29,2,FALSE))=FALSE,"",IF(ISNUMBER(F21),VLOOKUP($A21,List!$A$1:$B$29,2,FALSE))) | S21: =IF(IF(ISNUMBER(G21),VLOOKUP($A21,List!$A$1:$B$29,2,FALSE))=FALSE,"",IF(ISNUMBER(G21),VLOOKUP($A21,List!$A$1:$B$29,2,FALSE))) | T21: =IF(IF(ISNUMBER(H21),VLOOKUP($A21,List!$A$1:$B$29,2,FALSE))=FALSE,"",IF(ISNUMBER(H21),VLOOKUP($A21,List!$A$1:$B$29,2,FALSE))) | U21: =IF(IF(ISNUMBER(I21),VLOOKUP($A21,List!$A$1:$B$29,2,FALSE))=FALSE,"",IF(ISNUMBER(I21),VLOOKUP($A21,List!$A$1:$B$29,2,FALSE))) | ... Y21: =IF(IF(ISNUMBER(M21),VLOOKUP($A21,List!$A$1:$B$29,2,FALSE))=FALSE,"",IF(ISNUMBER(M21),VLOOKUP($A21,List!$A$1:$B$29,2,FALSE))) -> Boating gives me an outlet to socialize with family/friends
A22: 11 | B22: NA | C22: NA | D22: NA | E22: NA | F22: NA | G22: 0.88 | H22: NA | I22: NA | J22: NA | K22: NA | L22: NA | M22: NA | N22: =IF(IF(ISNUMBER(B22),VLOOKUP($A22,List!$A$1:$B$29,2,FALSE))=FALSE,"",IF(ISNUMBER(B22),VLOOKUP($A22,List!$A$1:$B$29,2,FALSE))) | O22: =IF(IF(ISNUMBER(C22),VLOOKUP($A22,List!$A$1:$B$29,2,FALSE))=FALSE,"",IF(ISNUMBER(C22),VLOOKUP($A22,List!$A$1:$B$29,2,FALSE))) | P22: =IF(IF(ISNUMBER(D22),VLOOKUP($A22,List!$A$1:$B$29,2,FALSE))=FALSE,"",IF(ISNUMBER(D22),VLOOKUP($A22,List!$A$1:$B$29,2,FALSE))) | Q22: =IF(IF(ISNUMBER(E22),VLOOKUP($A22,List!$A$1:$B$29,2,FALSE))=FALSE,"",IF(ISNUMBER(E22),VLOOKUP($A22,List!$A$1:$B$29,2,FALSE))) | R22: =IF(IF(ISNUMBER(F22),VLOOKUP($A22,List!$A$1:$B$29,2,FALSE))=FALSE,"",IF(ISNUMBER(F22),VLOOKUP($A22,List!$A$1:$B$29,2,FALSE))) | S22: =IF(IF(ISNUMBER(G22),VLOOKUP($A22,List!$A$1:$B$29,2,FALSE))=FALSE,"",IF(ISNUMBER(G22),VLOOKUP($A22,List!$A$1:$B$29,2,FALSE))) -> I tend to perform minor boat repairs and maintenance on my own | T22: =IF(IF(ISNUMBER(H22),VLOOKUP($A22,List!$A$1:$B$29,2,FALSE))=FALSE,"",IF(ISNUMBER(H22),VLOOKUP($A22,List!$A$1:$B$29,2,FALSE))) | U22: =IF(IF(ISNUMBER(I22),VLOOKUP($A22,List!$A$1:$B$29,2,FALSE))=FALSE,"",IF(ISNUMBER(I22),VLOOKUP($A22,List!$A$1:$B$29,2,FALSE))) | ... Y22: =IF(IF(ISNUMBER(M22),VLOOKUP($A22,List!$A$1:$B$29,2,FALSE))=FALSE,"",IF(ISNUMBER(M22),VLOOKUP($A22,List!$A$1:$B$29,2,FALSE)))
A23: 18 | B23: NA | C23: NA | D23: 0.72 | E23: NA | F23: NA | G23: NA | H23: NA | I23: NA | J23: NA | K23: NA | L23: NA | M23: NA | N23: =IF(IF(ISNUMBER(B23),VLOOKUP($A23,List!$A$1:$B$29,2,FALSE))=FALSE,"",IF(ISNUMBER(B23),VLOOKUP($A23,List!$A$1:$B$29,2,FALSE))) | O23: =IF(IF(ISNUMBER(C23),VLOOKUP($A23,List!$A$1:$B$29,2,FALSE))=FALSE,"",IF(ISNUMBER(C23),VLOOKUP($A23,List!$A$1:$B$29,2,FALSE))) | P23: =IF(IF(ISNUMBER(D23),VLOOKUP($A23,List!$A$1:$B$29,2,FALSE))=FALSE,"",IF(ISNUMBER(D23),VLOOKUP($A23,List!$A$1:$B$29,2,FALSE))) -> Boating gives me a feeling of adventure | Q23: =IF(IF(ISNUMBER(E23),VLOOKUP($A23,List!$A$1:$B$29,2,FALSE))=FALSE,"",IF(ISNUMBER(E23),VLOOKUP($A23,List!$A$1:$B$29,2,FALSE))) | R23: =IF(IF(ISNUMBER(F23),VLOOKUP($A23,List!$A$1:$B$29,2,FALSE))=FALSE,"",IF(ISNUMBER(F23),VLOOKUP($A23,List!$A$1:$B$29,2,FALSE))) | S23: =IF(IF(ISNUMBER(G23),VLOOKUP($A23,List!$A$1:$B$29,2,FALSE))=FALSE,"",IF(ISNUMBER(G23),VLOOKUP($A23,List!$A$1:$B$29,2,FALSE))) | T23: =IF(IF(ISNUMBER(H23),VLOOKUP($A23,List!$A$1:$B$29,2,FALSE))=FALSE,"",IF(ISNUMBER(H23),VLOOKUP($A23,List!$A$1:$B$29,2,FALSE))) | U23: =IF(IF(ISNUMBER(I23),VLOOKUP($A23,List!$A$1:$B$29,2,FALSE))=FALSE,"",IF(ISNUMBER(I23),VLOOKUP($A23,List!$A$1:$B$29,2,FALSE))) | ... Y23: =IF(IF(ISNUMBER(M23),VLOOKUP($A23,List!$A$1:$B$29,2,FALSE))=FALSE,"",IF(ISNUMBER(M23),VLOOKUP($A23,List!$A$1:$B$29,2,FALSE)))
A24: 21 | B24: NA | C24: NA | D24: 0.57 | E24: NA | F24: NA | G24: NA | H24: NA | I24: NA | J24: NA | K24: NA | L24: NA | M24: NA | N24: =IF(IF(ISNUMBER(B24),VLOOKUP($A24,List!$A$1:$B$29,2,FALSE))=FALSE,"",IF(ISNUMBER(B24),VLOOKUP($A24,List!$A$1:$B$29,2,FALSE))) | O24: =IF(IF(ISNUMBER(C24),VLOOKUP($A24,List!$A$1:$B$29,2,FALSE))=FALSE,"",IF(ISNUMBER(C24),VLOOKUP($A24,List!$A$1:$B$29,2,FALSE))) | P24: =IF(IF(ISNUMBER(D24),VLOOKUP($A24,List!$A$1:$B$29,2,FALSE))=FALSE,"",IF(ISNUMBER(D24),VLOOKUP($A24,List!$A$1:$B$29,2,FALSE))) -> Boating helps me escape from everyday life and relax | Q24: =IF(IF(ISNUMBER(E24),VLOOKUP($A24,List!$A$1:$B$29,2,FALSE))=FALSE,"",IF(ISNUMBER(E24),VLOOKUP($A24,List!$A$1:$B$29,2,FALSE))) | R24: =IF(IF(ISNUMBER(F24),VLOOKUP($A24,List!$A$1:$B$29,2,FALSE))=FALSE,"",IF(ISNUMBER(F24),VLOOKUP($A24,List!$A$1:$B$29,2,FALSE))) | S24: =IF(IF(ISNUMBER(G24),VLOOKUP($A24,List!$A$1:$B$29,2,FALSE))=FALSE,"",IF(ISNUMBER(G24),VLOOKUP($A24,List!$A$1:$B$29,2,FALSE))) | T24: =IF(IF(ISNUMBER(H24),VLOOKUP($A24,List!$A$1:$B$29,2,FALSE))=FALSE,"",IF(ISNUMBER(H24),VLOOKUP($A24,List!$A$1:$B$29,2,FALSE))) | U24: =IF(IF(ISNUMBER(I24),VLOOKUP($A24,List!$A$1:$B$29,2,FALSE))=FALSE,"",IF(ISNUMBER(I24),VLOOKUP($A24,List!$A$1:$B$29,2,FALSE))) | ... Y24: =IF(IF(ISNUMBER(M24),VLOOKUP($A24,List!$A$1:$B$29,2,FALSE))=FALSE,"",IF(ISNUMBER(M24),VLOOKUP($A24,List!$A$1:$B$29,2,FALSE)))
A25: 29 | B25: NA | C25: NA | D25: NA | E25: NA | F25: NA | G25: NA | H25: NA | I25: NA | J25: NA | K25: NA | L25: 0.9 | M25: NA | N25: =IF(IF(ISNUMBER(B25),VLOOKUP($A25,List!$A$1:$B$29,2,FALSE))=FALSE,"",IF(ISNUMBER(B25),VLOOKUP($A25,List!$A$1:$B$29,2,FALSE))) | O25: =IF(IF(ISNUMBER(C25),VLOOKUP($A25,List!$A$1:$B$29,2,FALSE))=FALSE,"",IF(ISNUMBER(C25),VLOOKUP($A25,List!$A$1:$B$29,2,FALSE))) | P25: =IF(IF(ISNUMBER(D25),VLOOKUP($A25,List!$A$1:$B$29,2,FALSE))=FALSE,"",IF(ISNUMBER(D25),VLOOKUP($A25,List!$A$1:$B$29,2,FALSE))) | Q25: =IF(IF(ISNUMBER(E25),VLOOKUP($A25,List!$A$1:$B$29,2,FALSE))=FALSE,"",IF(ISNUMBER(E25),VLOOKUP($A25,List!$A$1:$B$29,2,FALSE))) | R25: =IF(IF(ISNUMBER(F25),VLOOKUP($A25,List!$A$1:$B$29,2,FALSE))=FALSE,"",IF(ISNUMBER(F25),VLOOKUP($A25,List!$A$1:$B$29,2,FALSE))) | S25: =IF(IF(ISNUMBER(G25),VLOOKUP($A25,List!$A$1:$B$29,2,FALSE))=FALSE,"",IF(ISNUMBER(G25),VLOOKUP($A25,List!$A$1:$B$29,2,FALSE))) | T25: =IF(IF(ISNUMBER(H25),VLOOKUP($A25,List!$A$1:$B$29,2,FALSE))=FALSE,"",IF(ISNUMBER(H25),VLOOKUP($A25,List!$A$1:$B$29,2,FALSE))) | U25: =IF(IF(ISNUMBER(I25),VLOOKUP($A25,List!$A$1:$B$29,2,FALSE))=FALSE,"",IF(ISNUMBER(I25),VLOOKUP($A25,List!$A$1:$B$29,2,FALSE))) | ... Y25: =IF(IF(ISNUMBER(M25),VLOOKUP($A25,List!$A$1:$B$29,2,FALSE))=FALSE,"",IF(ISNUMBER(M25),VLOOKUP($A25,List!$A$1:$B$29,2,FALSE)))
A26: 1 | B26: NA | C26: NA | D26: NA | E26: NA | F26: NA | G26: NA | H26: NA | I26: NA | J26: NA | K26: 0.94 | L26: NA | M26: NA | N26: =IF(IF(ISNUMBER(B26),VLOOKUP($A26,List!$A$1:$B$29,2,FALSE))=FALSE,"",IF(ISNUMBER(B26),VLOOKUP($A26,List!$A$1:$B$29,2,FALSE))) | O26: =IF(IF(ISNUMBER(C26),VLOOKUP($A26,List!$A$1:$B$29,2,FALSE))=FALSE,"",IF(ISNUMBER(C26),VLOOKUP($A26,List!$A$1:$B$29,2,FALSE))) | P26: =IF(IF(ISNUMBER(D26),VLOOKUP($A26,List!$A$1:$B$29,2,FALSE))=FALSE,"",IF(ISNUMBER(D26),VLOOKUP($A26,List!$A$1:$B$29,2,FALSE))) | Q26: =IF(IF(ISNUMBER(E26),VLOOKUP($A26,List!$A$1:$B$29,2,FALSE))=FALSE,"",IF(ISNUMBER(E26),VLOOKUP($A26,List!$A$1:$B$29,2,FALSE))) | R26: =IF(IF(ISNUMBER(F26),VLOOKUP($A26,List!$A$1:$B$29,2,FALSE))=FALSE,"",IF(ISNUMBER(F26),VLOOKUP($A26,List!$A$1:$B$29,2,FALSE))) | S26: =IF(IF(ISNUMBER(G26),VLOOKUP($A26,List!$A$1:$B$29,2,FALSE))=FALSE,"",IF(ISNUMBER(G26),VLOOKUP($A26,List!$A$1:$B$29,2,FALSE))) | T26: =IF(IF(ISNUMBER(H26),VLOOKUP($A26,List!$A$1:$B$29,2,FALSE))=FALSE,"",IF(ISNUMBER(H26),VLOOKUP($A26,List!$A$1:$B$29,2,FALSE))) | U26: =IF(IF(ISNUMBER(I26),VLOOKUP($A26,List!$A$1:$B$29,2,FALSE))=FALSE,"",IF(ISNUMBER(I26),VLOOKUP($A26,List!$A$1:$B$29,2,FALSE))) | ... Y26: =IF(IF(ISNUMBER(M26),VLOOKUP($A26,List!$A$1:$B$29,2,FALSE))=FALSE,"",IF(ISNUMBER(M26),VLOOKUP($A26,List!$A$1:$B$29,2,FALSE)))
A27: 4 | B27: NA | C27: NA | D27: NA | E27: NA | F27: NA | G27: NA | H27: 0.84 | I27: NA | J27: NA | K27: NA | L27: NA | M27: NA | N27: =IF(IF(ISNUMBER(B27),VLOOKUP($A27,List!$A$1:$B$29,2,FALSE))=FALSE,"",IF(ISNUMBER(B27),VLOOKUP($A27,List!$A$1:$B$29,2,FALSE))) | O27: =IF(IF(ISNUMBER(C27),VLOOKUP($A27,List!$A$1:$B$29,2,FALSE))=FALSE,"",IF(ISNUMBER(C27),VLOOKUP($A27,List!$A$1:$B$29,2,FALSE))) | P27: =IF(IF(ISNUMBER(D27),VLOOKUP($A27,List!$A$1:$B$29,2,FALSE))=FALSE,"",IF(ISNUMBER(D27),VLOOKUP($A27,List!$A$1:$B$29,2,FALSE))) | Q27: =IF(IF(ISNUMBER(E27),VLOOKUP($A27,List!$A$1:$B$29,2,FALSE))=FALSE,"",IF(ISNUMBER(E27),VLOOKUP($A27,List!$A$1:$B$29,2,FALSE))) | R27: =IF(IF(ISNUMBER(F27),VLOOKUP($A27,List!$A$1:$B$29,2,FALSE))=FALSE,"",IF(ISNUMBER(F27),VLOOKUP($A27,List!$A$1:$B$29,2,FALSE))) | S27: =IF(IF(ISNUMBER(G27),VLOOKUP($A27,List!$A$1:$B$29,2,FALSE))=FALSE,"",IF(ISNUMBER(G27),VLOOKUP($A27,List!$A$1:$B$29,2,FALSE))) | T27: =IF(IF(ISNUMBER(H27),VLOOKUP($A27,List!$A$1:$B$29,2,FALSE))=FALSE,"",IF(ISNUMBER(H27),VLOOKUP($A27,List!$A$1:$B$29,2,FALSE))) -> I only consider buying a boat from a reputable brand | U27: =IF(IF(ISNUMBER(I27),VLOOKUP($A27,List!$A$1:$B$29,2,FALSE))=FALSE,"",IF(ISNUMBER(I27),VLOOKUP($A27,List!$A$1:$B$29,2,FALSE))) | ... Y27: =IF(IF(ISNUMBER(M27),VLOOKUP($A27,List!$A$1:$B$29,2,FALSE))=FALSE,"",IF(ISNUMBER(M27),VLOOKUP($A27,List!$A$1:$B$29,2,FALSE)))
A28: 19 | B28: NA | C28: NA | D28: 0.83 | E28: NA | F28: NA | G28: NA | H28: NA | I28: NA | J28: NA | K28: NA | L28: NA | M28: NA | N28: =IF(IF(ISNUMBER(B28),VLOOKUP($A28,List!$A$1:$B$29,2,FALSE))=FALSE,"",IF(ISNUMBER(B28),VLOOKUP($A28,List!$A$1:$B$29,2,FALSE))) | O28: =IF(IF(ISNUMBER(C28),VLOOKUP($A28,List!$A$1:$B$29,2,FALSE))=FALSE,"",IF(ISNUMBER(C28),VLOOKUP($A28,List!$A$1:$B$29,2,FALSE))) | P28: =IF(IF(ISNUMBER(D28),VLOOKUP($A28,List!$A$1:$B$29,2,FALSE))=FALSE,"",IF(ISNUMBER(D28),VLOOKUP($A28,List!$A$1:$B$29,2,FALSE))) -> Boating allows me to experience nature | Q28: =IF(IF(ISNUMBER(E28),VLOOKUP($A28,List!$A$1:$B$29,2,FALSE))=FALSE,"",IF(ISNUMBER(E28),VLOOKUP($A28,List!$A$1:$B$29,2,FALSE))) | R28: =IF(IF(ISNUMBER(F28),VLOOKUP($A28,List!$A$1:$B$29,2,FALSE))=FALSE,"",IF(ISNUMBER(F28),VLOOKUP($A28,List!$A$1:$B$29,2,FALSE))) | S28: =IF(IF(ISNUMBER(G28),VLOOKUP($A28,List!$A$1:$B$29,2,FALSE))=FALSE,"",IF(ISNUMBER(G28),VLOOKUP($A28,List!$A$1:$B$29,2,FALSE))) | T28: =IF(IF(ISNUMBER(H28),VLOOKUP($A28,List!$A$1:$B$29,2,FALSE))=FALSE,"",IF(ISNUMBER(H28),VLOOKUP($A28,List!$A$1:$B$29,2,FALSE))) | U28: =IF(IF(ISNUMBER(I28),VLOOKUP($A28,List!$A$1:$B$29,2,FALSE))=FALSE,"",IF(ISNUMBER(I28),VLOOKUP($A28,List!$A$1:$B$29,2,FALSE))) | ... Y28: =IF(IF(ISNUMBER(M28),VLOOKUP($A28,List!$A$1:$B$29,2,FALSE))=FALSE,"",IF(ISNUMBER(M28),VLOOKUP($A28,List!$A$1:$B$29,2,FALSE)))
A29: 8 | B29: NA | C29: NA | D29: NA | E29: NA | F29: NA | G29: NA | H29: NA | I29: NA | J29: 0.95 | K29: NA | L29: NA | M29: NA | N29: =IF(IF(ISNUMBER(B29),VLOOKUP($A29,List!$A$1:$B$29,2,FALSE))=FALSE,"",IF(ISNUMBER(B29),VLOOKUP($A29,List!$A$1:$B$29,2,FALSE))) | O29: =IF(IF(ISNUMBER(C29),VLOOKUP($A29,List!$A$1:$B$29,2,FALSE))=FALSE,"",IF(ISNUMBER(C29),VLOOKUP($A29,List!$A$1:$B$29,2,FALSE))) | P29: =IF(IF(ISNUMBER(D29),VLOOKUP($A29,List!$A$1:$B$29,2,FALSE))=FALSE,"",IF(ISNUMBER(D29),VLOOKUP($A29,List!$A$1:$B$29,2,FALSE))) | Q29: =IF(IF(ISNUMBER(E29),VLOOKUP($A29,List!$A$1:$B$29,2,FALSE))=FALSE,"",IF(ISNUMBER(E29),VLOOKUP($A29,List!$A$1:$B$29,2,FALSE))) | R29: =IF(IF(ISNUMBER(F29),VLOOKUP($A29,List!$A$1:$B$29,2,FALSE))=FALSE,"",IF(ISNUMBER(F29),VLOOKUP($A29,List!$A$1:$B$29,2,FALSE))) | S29: =IF(IF(ISNUMBER(G29),VLOOKUP($A29,List!$A$1:$B$29,2,FALSE))=FALSE,"",IF(ISNUMBER(G29),VLOOKUP($A29,List!$A$1:$B$29,2,FALSE))) | T29: =IF(IF(ISNUMBER(H29),VLOOKUP($A29,List!$A$1:$B$29,2,FALSE))=FALSE,"",IF(ISNUMBER(H29),VLOOKUP($A29,List!$A$1:$B$29,2,FALSE))) | U29: =IF(IF(ISNUMBER(I29),VLOOKUP($A29,List!$A$1:$B$29,2,FALSE))=FALSE,"",IF(ISNUMBER(I29),VLOOKUP($A29,List!$A$1:$B$29,2,FALSE))) | ... Y29: =IF(IF(ISNUMBER(M29),VLOOKUP($A29,List!$A$1:$B$29,2,FALSE))=FALSE,"",IF(ISNUMBER(M29),VLOOKUP($A29,List!$A$1:$B$29,2,FALSE)))
A30: 2 | B30: NA | C30: NA | D30: NA | E30: NA | F30: 0.83 | G30: NA | H30: NA | I30: NA | J30: NA | K30: NA | L30: NA | M30: NA | N30: =IF(IF(ISNUMBER(B30),VLOOKUP($A30,List!$A$1:$B$29,2,FALSE))=FALSE,"",IF(ISNUMBER(B30),VLOOKUP($A30,List!$A$1:$B$29,2,FALSE))) | O30: =IF(IF(ISNUMBER(C30),VLOOKUP($A30,List!$A$1:$B$29,2,FALSE))=FALSE,"",IF(ISNUMBER(C30),VLOOKUP($A30,List!$A$1:$B$29,2,FALSE))) | P30: =IF(IF(ISNUMBER(D30),VLOOKUP($A30,List!$A$1:$B$29,2,FALSE))=FALSE,"",IF(ISNUMBER(D30),VLOOKUP($A30,List!$A$1:$B$29,2,FALSE))) | Q30: =IF(IF(ISNUMBER(E30),VLOOKUP($A30,List!$A$1:$B$29,2,FALSE))=FALSE,"",IF(ISNUMBER(E30),VLOOKUP($A30,List!$A$1:$B$29,2,FALSE))) | R30: =IF(IF(ISNUMBER(F30),VLOOKUP($A30,List!$A$1:$B$29,2,FALSE))=FALSE,"",IF(ISNUMBER(F30),VLOOKUP($A30,List!$A$1:$B$29,2,FALSE))) -> When buying a bot, getting the lowest P is more important than brand | S30: =IF(IF(ISNUMBER(G30),VLOOKUP($A30,List!$A$1:$B$29,2,FALSE))=FALSE,"",IF(ISNUMBER(G30),VLOOKUP($A30,List!$A$1:$B$29,2,FALSE))) | T30: =IF(IF(ISNUMBER(H30),VLOOKUP($A30,List!$A$1:$B$29,2,FALSE))=FALSE,"",IF(ISNUMBER(H30),VLOOKUP($A30,List!$A$1:$B$29,2,FALSE))) | U30: =IF(IF(ISNUMBER(I30),VLOOKUP($A30,List!$A$1:$B$29,2,FALSE))=FALSE,"",IF(ISNUMBER(I30),VLOOKUP($A30,List!$A$1:$B$29,2,FALSE))) | ... Y30: =IF(IF(ISNUMBER(M30),VLOOKUP($A30,List!$A$1:$B$29,2,FALSE))=FALSE,"",IF(ISNUMBER(M30),VLOOKUP($A30,List!$A$1:$B$29,2,FALSE)))
